Workbook

Sheet Practice Tasks
A1: Advanced Excel Practice - Assignment 2
A3: 1 | B3: Clean City and Property Type into new columns - consistent spacing and capitalisation throughout.
A4: 2 | B4: Flag exact duplicate lease records (same Property Name + City + Lease Start Date).
A5: 3 | B5: For each property, pull in its State by matching the cleaned City against the 'City-State Lookup' sheet.
A6: 4 | B6: For each property, pull in its Region - City to State to Region - using both lookup sheets together.
A7: 5 | B7: For any property whose City has no match in the lookup table, show 'Not Mapped' instead of an error.
A8: 6 | B8: Assign each active lease a Rent Band (Low/Medium/High/Premium) based on the 'Rent Band Table' thresholds.
A9: 7 | B9: For each active lease, retrieve the benchmark rent per sqft for its Property Type + City combination from 'Benchmark Rate Card' (two conditions, one lookup).
A10: 8 | B10: Calculate each property's actual rent per sqft, and compare it to the benchmark - flag as 'Above Benchmark' or 'At/Below Benchmark'.
A11: 9 | B11: Split the 'Tenant Info' column into two separate columns: Tenant Name and Tenant Industry.
A12: 10 | B12: Calculate the remaining lease term in months as of today, for active leases only.
A13: 11 | B13: Flag any active lease with fewer than 12 months remaining as 'Renewal Watch'.
A14: 12 | B14: Find the single largest active lease (by Monthly Rent) in each City - show the Property Name next to each City, not just the rent amount.
... A22: 20 | B22: Apply conditional formatting: highlight any lease flagged 'Renewal Watch' in task 11.

Sheet Portfolio Data (Raw)
A1: Property ID | B1: Property Name | C1: City | D1: Property Type | E1: Total Area (sqft) | F1: Lease Status | G1: Tenant Info | H1: Lease Start Date | I1: Lease End Date | J1: Monthly Rent (INR)
A2: R001 | B2: Emerald Corporate Towers | C2: Bengaluru | D2: Office | E2: 52000 | F2: Active | G2: Nimbus Cloud Pvt Ltd - IT Services | H2: 2022-05-01 | I2: 2028-04-30 | J2: 2150000
A3: R002 | B3: Emerald Corporate Towers | C3: Bengaluru | D3: Office | E3: 52000 | F3: Active | G3: Nimbus Cloud Pvt Ltd - IT Services | H3: 2022-05-01 | I3: 2028-04-30 | J3: 2150000
A4: R003 | B4: Vista Business Bay | C4: hyderabad | D4: Office | E4: 68000 | F4: Active | G4: Quantum Analytics - IT Services | H4: 2021-08-15 | I4: 2027-03-14 | J4: 2680000
A5: R004 | B5: Vista Business Bay | C5: Hyderabad | D5: office | E5: 68000 | F5: active | G5: Quantum Analytics - IT Services | H5: 2021-08-15 | I5: 2027-03-14 | J5: 2680000
A6: R005 | B6: Palm Grove Mall | C6: Chennai | D6: Retail | E6: 31000 | F6: Active | G6: Spice Route Foods - F&B | H6: 2023-03-10 | I6: 2029-03-09 | J6: 1320000
A7: R006 | B7: Palm Grove Mall | C7: CHENNAI | D7: Retail | E7: 31000 | F7: vacant
A8: R007 | B8: Anchor Point Warehouse | C8: Mumbai | D8: Industrial | E8: 145000 | F8: Active | G8: FreightLine Cargo - Logistics | H8: 2020-01-20 | I8: 2025-01-19 | J8: 3550000
A9: R008 | B9: Anchor Point Warehouse | C9: Mumbai | D9: Industrial | E9: 145000 | F9: Active | G9: FreightLine Cargo - Logistics | H9: 2020-01-20 | I9: 2025-01-19 | J9: 3550000
A10: R009 | B10: Silver Oak Tech Park | C10: Pune | D10: Office | E10: 47000 | F10: Active | G10: Beacon Software - IT Services | H10: 2023-06-01 | I10: 2027-05-31 | J10: 1890000
A11: R010 | B11: Silver Oak Tech Park | C11: pune | D11: office | E11: 47000 | F11: Active | G11: Beacon Software - IT Services | H11: 2023-06-01 | I11: 2027-05-31 | J11: 1890000
A12: R011 | B12: Coral Street Plaza | C12: Bengaluru | D12: Retail | E12: 24000 | F12: Active | G12: Urban Threads - Fashion Retail | H12: 2024-01-05 | I12: 2028-01-04 | J12: 990000
A13: R012 | B13: Coral Street Plaza | C13: Bengaluru | D13: Retail | E13: 24000 | F13: vacant
A14: R013 | B14: Northgate Logistics Hub | C14: Delhi | D14: Industrial | E14: 112000 | F14: Active | G14: SwiftCargo Movers - Logistics | H14: 2019-11-11 | I14: 2024-11-10 | J14: 2980000
A15: R014 | B15: Northgate Logistics Hub | C15: Delhi | D15: industrial | E15: 112000 | F15: Active | G15: SwiftCargo Movers - Logistics | H15: 2019-11-11 | I15: 2024-11-10 | J15: 2980000
A16: R015 | B16: Zenith IT Campus | C16: hyderabad | D16: Office | E16: 81000 | F16: Active | G16: CoreStack Systems - IT Services | H16: 2022-09-01 | I16: 2029-08-31 | J16: 3120000
A17: R016 | B17: Zenith IT Campus | C17: Hyderabad | D17: Office | E17: 81000 | F17: Active | G17: CoreStack Systems - IT Services | H17: 2022-09-01 | I17: 2029-08-31 | J17: 3120000
A18: R017 | B18: Marina Bay Retail Court | C18: Chennai | D18: Retail | E18: 19500 | F18: Active | G18: Coastal Bites - F&B | H18: 2024-04-18 | I18: 2027-01-17 | J18: 870000
A19: R018 | B19: Marina Bay Retail Court | C19: chennai | D19: retail | E19: 19500 | F19: Active | G19: Coastal Bites - F&B | H19: 2024-04-18 | I19: 2027-01-17 | J19: 870000
A20: R019 | B20: Summit Business Center | C20: Pune | D20: Office | E20: 39000 | F20: Active | G20: Alpine Consulting - Professional Services | H20: 2022-02-14 | I20: 2026-11-13 | J20: 1560000
A21: R020 | B21: Summit Business Center | C21: Pune | D21: Office | E21: 39000 | F21: vacant
A22: R021 | B22: Blue Ridge Warehouse | C22: Mumbai | D22: Industrial | E22: 98000 | F22: Active | G22: Continental Freight - Logistics | H22: 2021-07-07 | I22: 2028-07-06 | J22: 2450000
A23: R022 | B23: Ashoka Trade Center | C23: Noida | D23: Office | E23: 44000 | F23: Active | G23: Pioneer Traders - Professional Services | H23: 2023-10-01 | I23: 2027-04-30 | J23: 1780000
A24: R023 | B24: Lotus Corporate Park | C24: Bengaluru | D24: Office | E24: 59000 | F24: Active | G24: Vertex BioLabs - Pharma | H24: 2020-12-01 | I24: 2026-10-30 | J24: 2340000
A25: R024 | B25: Lotus Corporate Park | C25: Bengaluru | D25: Office | E25: 59000 | F25: Active | G25: Vertex BioLabs - Pharma | H25: 2020-12-01 | I25: 2026-10-30 | J25: 2340000
A26: R025 | B26: Golden Harbor Mall | C26: Mumbai | D26: Retail | E26: 27500 | F26: Active | G26: Bay Fashion House - Fashion Retail | H26: 2023-08-20 | I26: 2029-08-19 | J26: 1180000
A27: R026 | B27: Falcon Industrial Estate | C27: Chennai | D27: Industrial | E27: 87000 | F27: Active | G27: TransGlobal Logistics - Logistics | H27: 2022-03-15 | I27: 2025-10-14 | J27: 2210000
A28: R027 | B28: Falcon Industrial Estate | C28: Chennai | D28: industrial | E28: 87000 | F28: Active | G28: TransGlobal Logistics - Logistics | H28: 2022-03-15 | I28: 2025-10-14 | J28: 2210000

Sheet Portfolio Data (Modified)
A1: Property ID | B1: Property Name | C1: City | D1: Property Type | E1: Total Area (sqft) | F1: Lease Status | G1: Lease Start Date | H1: Lease End Date | I1: Monthly Rent (INR) | J1: Duplicate Records | K1: State | L1: Region | M1: Rent Band | N1: Benchmark Rent | O1: Tenant Name | P1: Tenant Industry | Q1: Actual Rent per sqft | R1: Benchmark flag | S1: Months Remaining | T1: Renewal Watch | U1: Rank Monthly Rent | V1: Priority
A2: R001 | B2: Emerald Corporate Towers | C2: Bengaluru | D2: Office | E2: 52000 | F2: Active | G2: 2022-05-01 | H2: 2028-04-30 | I2: 2150000 | J2: =COUNTIFS($B$2:$B$28,B2,$C$2:$C$28,C2,$G$2:$G$28,G2) -> 2 | K2: =IFERROR(INDEX('City-State Lookup'!$B$2:$B$7,MATCH('Portfolio Data (Modified)'!C2,'City-State Lookup'!$A$2:$A$7,0)),"Not Mapped") -> Karnataka | L2: =IFERROR(INDEX('State-Region Lookup'!$B$2:$B$6,MATCH('Portfolio Data (Modified)'!K2,'State-Region Lookup'!$A$2:$A$6,0)),"Not Mapped") -> South | M2: =IF(F2<>"Active","",VLOOKUP(I2,'Rent Band Table'!$A$2:$B$5,2,TRUE)) -> High | N2: =IFERROR(IF(F2="Active",INDEX('Benchmark Rate Card'!$B$2:$G$4,MATCH('Portfolio Data (Modified)'!D2,'Benchmark Rate Card'!$A$2:$A$4,0),MATCH('Portfolio Data (Modified)'!C2,'Benchmark Rate Card'!$B$1:$G$1,0)),""),"") -> 42 | O2: Nimbus Cloud Pvt Ltd | P2: IT Services | Q2: =IF(F2="Active",ROUND(I2/E2,2),"") -> 41.35 | R2: =IF(F2="Active",_xlfn.IFS(Q2>N2,"Above Benchmark",Q2<=N2,"At/Below Benchmark"),"") -> At/Below Benchmark | S2: =IFERROR(IF(F2="Active",DATEDIF(TODAY(),H2,"m"),""),"Expired") -> 19 | T2: =IF(OR(S2<12,S2="Expired"),"Renewal Watch","") | U2: =IFERROR(RANK(I2,$I$2:$I$28,0),"") -> 14 | V2: =IF(F2<>"Active","",_xlfn.IFS(S2="Expired","Urgent",S2<3,"Urgent",S2<12,"Watch",S2>=12,"OK")) -> OK
A3: R002 | B3: Emerald Corporate Towers | C3: Bengaluru | D3: Office | E3: 52000 | F3: Active | G3: 2022-05-01 | H3: 2028-04-30 | I3: 2150000 | J3: =COUNTIFS($B$2:$B$28,B3,$C$2:$C$28,C3,$G$2:$G$28,G3) -> 2 | K3: =IFERROR(INDEX('City-State Lookup'!$B$2:$B$7,MATCH('Portfolio Data (Modified)'!C3,'City-State Lookup'!$A$2:$A$7,0)),"Not Mapped") -> Karnataka | L3: =IFERROR(INDEX('State-Region Lookup'!$B$2:$B$6,MATCH('Portfolio Data (Modified)'!K3,'State-Region Lookup'!$A$2:$A$6,0)),"Not Mapped") -> South | M3: =IF(F3<>"Active","",VLOOKUP(I3,'Rent Band Table'!$A$2:$B$5,2,TRUE)) -> High | N3: =IFERROR(IF(F3="Active",INDEX('Benchmark Rate Card'!$B$2:$G$4,MATCH('Portfolio Data (Modified)'!D3,'Benchmark Rate Card'!$A$2:$A$4,0),MATCH('Portfolio Data (Modified)'!C3,'Benchmark Rate Card'!$B$1:$G$1,0)),""),"") -> 42 | O3: Nimbus Cloud Pvt Ltd | P3: IT Services | Q3: =IF(F3="Active",ROUND(I3/E3,2),"") -> 41.35 | R3: =IF(F3="Active",_xlfn.IFS(Q3>N3,"Above Benchmark",Q3<=N3,"At/Below Benchmark"),"") -> At/Below Benchmark | S3: =IFERROR(IF(F3="Active",DATEDIF(TODAY(),H3,"m"),""),"Expired") -> 19 | T3: =IF(OR(S3<12,S3="Expired"),"Renewal Watch","") | U3: =IFERROR(RANK(I3,$I$2:$I$28,0),"") -> 14 | V3: =IF(F3<>"Active","",_xlfn.IFS(S3="Expired","Urgent",S3<3,"Urgent",S3<12,"Watch",S3>=12,"OK")) -> OK
A4: R003 | B4: Vista Business Bay | C4: Hyderabad | D4: Office | E4: 68000 | F4: Active | G4: 2021-08-15 | H4: 2027-03-14 | I4: 2680000 | J4: =COUNTIFS($B$2:$B$28,B4,$C$2:$C$28,C4,$G$2:$G$28,G4) -> 1 | K4: =IFERROR(INDEX('City-State Lookup'!$B$2:$B$7,MATCH('Portfolio Data (Modified)'!C4,'City-State Lookup'!$A$2:$A$7,0)),"Not Mapped") -> Telangana | L4: =IFERROR(INDEX('State-Region Lookup'!$B$2:$B$6,MATCH('Portfolio Data (Modified)'!K4,'State-Region Lookup'!$A$2:$A$6,0)),"Not Mapped") -> South | M4: =IF(F4<>"Active","",VLOOKUP(I4,'Rent Band Table'!$A$2:$B$5,2,TRUE)) -> High | N4: =IFERROR(IF(F4="Active",INDEX('Benchmark Rate Card'!$B$2:$G$4,MATCH('Portfolio Data (Modified)'!D4,'Benchmark Rate Card'!$A$2:$A$4,0),MATCH('Portfolio Data (Modified)'!C4,'Benchmark Rate Card'!$B$1:$G$1,0)),""),"") -> 39 | O4: Quantum Analytics | P4: IT Services | Q4: =IF(F4="Active",ROUND(I4/E4,2),"") -> 39.41 | R4: =IF(F4="Active",_xlfn.IFS(Q4>N4,"Above Benchmark",Q4<=N4,"At/Below Benchmark"),"") -> Above Benchmark | S4: =IFERROR(IF(F4="Active",DATEDIF(TODAY(),H4,"m"),""),"Expired") -> 5 | T4: =IF(OR(S4<12,S4="Expired"),"Renewal Watch","") -> Renewal Watch | U4: =IFERROR(RANK(I4,$I$2:$I$28,0),"") -> 7 | V4: =IF(F4<>"Active","",_xlfn.IFS(S4="Expired","Urgent",S4<3,"Urgent",S4<12,"Watch",S4>=12,"OK")) -> Watch
A5: R004 | B5: Vista Business Bay | C5: Hyderabad | D5: Office | E5: 68000 | F5: Active | G5: 2021-08-15 | H5: 2027-03-14 | I5: 2680000 | J5: =COUNTIFS($B$2:$B$28,B5,$C$2:$C$28,C5,$G$2:$G$28,G5) -> 1 | K5: =IFERROR(INDEX('City-State Lookup'!$B$2:$B$7,MATCH('Portfolio Data (Modified)'!C5,'City-State Lookup'!$A$2:$A$7,0)),"Not Mapped") -> Telangana | L5: =IFERROR(INDEX('State-Region Lookup'!$B$2:$B$6,MATCH('Portfolio Data (Modified)'!K5,'State-Region Lookup'!$A$2:$A$6,0)),"Not Mapped") -> South | M5: =IF(F5<>"Active","",VLOOKUP(I5,'Rent Band Table'!$A$2:$B$5,2,TRUE)) -> High | N5: =IFERROR(IF(F5="Active",INDEX('Benchmark Rate Card'!$B$2:$G$4,MATCH('Portfolio Data (Modified)'!D5,'Benchmark Rate Card'!$A$2:$A$4,0),MATCH('Portfolio Data (Modified)'!C5,'Benchmark Rate Card'!$B$1:$G$1,0)),""),"") -> 39 | O5: Quantum Analytics | P5: IT Services | Q5: =IF(F5="Active",ROUND(I5/E5,2),"") -> 39.41 | R5: =IF(F5="Active",_xlfn.IFS(Q5>N5,"Above Benchmark",Q5<=N5,"At/Below Benchmark"),"") -> Above Benchmark | S5: =IFERROR(IF(F5="Active",DATEDIF(TODAY(),H5,"m"),""),"Expired") -> 5 | T5: =IF(OR(S5<12,S5="Expired"),"Renewal Watch","") -> Renewal Watch | U5: =IFERROR(RANK(I5,$I$2:$I$28,0),"") -> 7 | V5: =IF(F5<>"Active","",_xlfn.IFS(S5="Expired","Urgent",S5<3,"Urgent",S5<12,"Watch",S5>=12,"OK")) -> Watch
A6: R005 | B6: Palm Grove Mall | C6: Chennai | D6: Retail | E6: 31000 | F6: Active | G6: 2023-03-10 | H6: 2029-03-09 | I6: 1320000 | J6: =COUNTIFS($B$2:$B$28,B6,$C$2:$C$28,C6,$G$2:$G$28,G6) -> 1 | K6: =IFERROR(INDEX('City-State Lookup'!$B$2:$B$7,MATCH('Portfolio Data (Modified)'!C6,'City-State Lookup'!$A$2:$A$7,0)),"Not Mapped") -> Tamil Nadu | L6: =IFERROR(INDEX('State-Region Lookup'!$B$2:$B$6,MATCH('Portfolio Data (Modified)'!K6,'State-Region Lookup'!$A$2:$A$6,0)),"Not Mapped") -> South | M6: =IF(F6<>"Active","",VLOOKUP(I6,'Rent Band Table'!$A$2:$B$5,2,TRUE)) -> Medium | N6: =IFERROR(IF(F6="Active",INDEX('Benchmark Rate Card'!$B$2:$G$4,MATCH('Portfolio Data (Modified)'!D6,'Benchmark Rate Card'!$A$2:$A$4,0),MATCH('Portfolio Data (Modified)'!C6,'Benchmark Rate Card'!$B$1:$G$1,0)),""),"") -> 47 | O6: Spice Route Foods | P6: F&B | Q6: =IF(F6="Active",ROUND(I6/E6,2),"") -> 42.58 | R6: =IF(F6="Active",_xlfn.IFS(Q6>N6,"Above Benchmark",Q6<=N6,"At/Below Benchmark"),"") -> At/Below Benchmark | S6: =IFERROR(IF(F6="Active",DATEDIF(TODAY(),H6,"m"),""),"Expired") -> 29 | T6: =IF(OR(S6<12,S6="Expired"),"Renewal Watch","") | U6: =IFERROR(RANK(I6,$I$2:$I$28,0),"") -> 20 | V6: =IF(F6<>"Active","",_xlfn.IFS(S6="Expired","Urgent",S6<3,"Urgent",S6<12,"Watch",S6>=12,"OK")) -> OK
A7: R006 | B7: Palm Grove Mall | C7: Chennai | D7: Retail | E7: 31000 | F7: Vacant | J7: =COUNTIFS($B$2:$B$28,B7,$C$2:$C$28,C7,$G$2:$G$28,G7) -> 0 | K7: =IFERROR(INDEX('City-State Lookup'!$B$2:$B$7,MATCH('Portfolio Data (Modified)'!C7,'City-State Lookup'!$A$2:$A$7,0)),"Not Mapped") -> Tamil Nadu | L7: =IFERROR(INDEX('State-Region Lookup'!$B$2:$B$6,MATCH('Portfolio Data (Modified)'!K7,'State-Region Lookup'!$A$2:$A$6,0)),"Not Mapped") -> South | M7: =IF(F7<>"Active","",VLOOKUP(I7,'Rent Band Table'!$A$2:$B$5,2,TRUE)) | N7: =IFERROR(IF(F7="Active",INDEX('Benchmark Rate Card'!$B$2:$G$4,MATCH('Portfolio Data (Modified)'!D7,'Benchmark Rate Card'!$A$2:$A$4,0),MATCH('Portfolio Data (Modified)'!C7,'Benchmark Rate Card'!$B$1:$G$1,0)),""),"") | Q7: =IF(F7="Active",ROUND(I7/E7,2),"") | R7: =IF(F7="Active",_xlfn.IFS(Q7>N7,"Above Benchmark",Q7<=N7,"At/Below Benchmark"),"") | S7: =IFERROR(IF(F7="Active",DATEDIF(TODAY(),H7,"m"),""),"Expired") | T7: =IF(OR(S7<12,S7="Expired"),"Renewal Watch","") | U7: =IFERROR(RANK(I7,$I$2:$I$28,0),"") | V7: =IF(F7<>"Active","",_xlfn.IFS(S7="Expired","Urgent",S7<3,"Urgent",S7<12,"Watch",S7>=12,"OK"))
A8: R007 | B8: Anchor Point Warehouse | C8: Mumbai | D8: Industrial | E8: 145000 | F8: Active | G8: 2020-01-20 | H8: 2025-01-19 | I8: 3550000 | J8: =COUNTIFS($B$2:$B$28,B8,$C$2:$C$28,C8,$G$2:$G$28,G8) -> 2 | K8: =IFERROR(INDEX('City-State Lookup'!$B$2:$B$7,MATCH('Portfolio Data (Modified)'!C8,'City-State Lookup'!$A$2:$A$7,0)),"Not Mapped") -> Maharashtra | L8: =IFERROR(INDEX('State-Region Lookup'!$B$2:$B$6,MATCH('Portfolio Data (Modified)'!K8,'State-Region Lookup'!$A$2:$A$6,0)),"Not Mapped") -> West | M8: =IF(F8<>"Active","",VLOOKUP(I8,'Rent Band Table'!$A$2:$B$5,2,TRUE)) -> Premium | N8: =IFERROR(IF(F8="Active",INDEX('Benchmark Rate Card'!$B$2:$G$4,MATCH('Portfolio Data (Modified)'!D8,'Benchmark Rate Card'!$A$2:$A$4,0),MATCH('Portfolio Data (Modified)'!C8,'Benchmark Rate Card'!$B$1:$G$1,0)),""),"") -> 28 | O8: FreightLine Cargo | P8: Logistics | Q8: =IF(F8="Active",ROUND(I8/E8,2),"") -> 24.48 | R8: =IF(F8="Active",_xlfn.IFS(Q8>N8,"Above Benchmark",Q8<=N8,"At/Below Benchmark"),"") -> At/Below Benchmark | S8: =IFERROR(IF(F8="Active",DATEDIF(TODAY(),H8,"m"),""),"Expired") -> Expired | T8: =IF(OR(S8<12,S8="Expired"),"Renewal Watch","") -> Renewal Watch | U8: =IFERROR(RANK(I8,$I$2:$I$28,0),"") -> 1 | V8: =IF(F8<>"Active","",_xlfn.IFS(S8="Expired","Urgent",S8<3,"Urgent",S8<12,"Watch",S8>=12,"OK")) -> Urgent
A9: R008 | B9: Anchor Point Warehouse | C9: Mumbai | D9: Industrial | E9: 145000 | F9: Active | G9: 2020-01-20 | H9: 2025-01-19 | I9: 3550000 | J9: =COUNTIFS($B$2:$B$28,B9,$C$2:$C$28,C9,$G$2:$G$28,G9) -> 2 | K9: =IFERROR(INDEX('City-State Lookup'!$B$2:$B$7,MATCH('Portfolio Data (Modified)'!C9,'City-State Lookup'!$A$2:$A$7,0)),"Not Mapped") -> Maharashtra | L9: =IFERROR(INDEX('State-Region Lookup'!$B$2:$B$6,MATCH('Portfolio Data (Modified)'!K9,'State-Region Lookup'!$A$2:$A$6,0)),"Not Mapped") -> West | M9: =IF(F9<>"Active","",VLOOKUP(I9,'Rent Band Table'!$A$2:$B$5,2,TRUE)) -> Premium | N9: =IFERROR(IF(F9="Active",INDEX('Benchmark Rate Card'!$B$2:$G$4,MATCH('Portfolio Data (Modified)'!D9,'Benchmark Rate Card'!$A$2:$A$4,0),MATCH('Portfolio Data (Modified)'!C9,'Benchmark Rate Card'!$B$1:$G$1,0)),""),"") -> 28 | O9: FreightLine Cargo | P9: Logistics | Q9: =IF(F9="Active",ROUND(I9/E9,2),"") -> 24.48 | R9: =IF(F9="Active",_xlfn.IFS(Q9>N9,"Above Benchmark",Q9<=N9,"At/Below Benchmark"),"") -> At/Below Benchmark | S9: =IFERROR(IF(F9="Active",DATEDIF(TODAY(),H9,"m"),""),"Expired") -> Expired | T9: =IF(OR(S9<12,S9="Expired"),"Renewal Watch","") -> Renewal Watch | U9: =IFERROR(RANK(I9,$I$2:$I$28,0),"") -> 1 | V9: =IF(F9<>"Active","",_xlfn.IFS(S9="Expired","Urgent",S9<3,"Urgent",S9<12,"Watch",S9>=12,"OK")) -> Urgent
A10: R009 | B10: Silver Oak Tech Park | C10: Pune | D10: Office | E10: 47000 | F10: Active | G10: 2023-06-01 | H10: 2027-05-31 | I10: 1890000 | J10: =COUNTIFS($B$2:$B$28,B10,$C$2:$C$28,C10,$G$2:$G$28,G10) -> 2 | K10: =IFERROR(INDEX('City-State Lookup'!$B$2:$B$7,MATCH('Portfolio Data (Modified)'!C10,'City-State Lookup'!$A$2:$A$7,0)),"Not Mapped") -> Maharashtra | L10: =IFERROR(INDEX('State-Region Lookup'!$B$2:$B$6,MATCH('Portfolio Data (Modified)'!K10,'State-Region Lookup'!$A$2:$A$6,0)),"Not Mapped") -> West | M10: =IF(F10<>"Active","",VLOOKUP(I10,'Rent Band Table'!$A$2:$B$5,2,TRUE)) -> Medium | N10: =IFERROR(IF(F10="Active",INDEX('Benchmark Rate Card'!$B$2:$G$4,MATCH('Portfolio Data (Modified)'!D10,'Benchmark Rate Card'!$A$2:$A$4,0),MATCH('Portfolio Data (Modified)'!C10,'Benchmark Rate Card'!$B$1:$G$1,0)),""),"") -> 43 | O10: Beacon Software | P10: IT Services | Q10: =IF(F10="Active",ROUND(I10/E10,2),"") -> 40.21 | R10: =IF(F10="Active",_xlfn.IFS(Q10>N10,"Above Benchmark",Q10<=N10,"At/Below Benchmark"),"") -> At/Below Benchmark | S10: =IFERROR(IF(F10="Active",DATEDIF(TODAY(),H10,"m"),""),"Expired") -> 8 | T10: =IF(OR(S10<12,S10="Expired"),"Renewal Watch","") -> Renewal Watch | U10: =IFERROR(RANK(I10,$I$2:$I$28,0),"") -> 16 | V10: =IF(F10<>"Active","",_xlfn.IFS(S10="Expired","Urgent",S10<3,"Urgent",S10<12,"Watch",S10>=12,"OK")) -> Watch
A11: R010 | B11: Silver Oak Tech Park | C11: Pune | D11: Office | E11: 47000 | F11: Active | G11: 2023-06-01 | H11: 2027-05-31 | I11: 1890000 | J11: =COUNTIFS($B$2:$B$28,B11,$C$2:$C$28,C11,$G$2:$G$28,G11) -> 2 | K11: =IFERROR(INDEX('City-State Lookup'!$B$2:$B$7,MATCH('Portfolio Data (Modified)'!C11,'City-State Lookup'!$A$2:$A$7,0)),"Not Mapped") -> Maharashtra | L11: =IFERROR(INDEX('State-Region Lookup'!$B$2:$B$6,MATCH('Portfolio Data (Modified)'!K11,'State-Region Lookup'!$A$2:$A$6,0)),"Not Mapped") -> West | M11: =IF(F11<>"Active","",VLOOKUP(I11,'Rent Band Table'!$A$2:$B$5,2,TRUE)) -> Medium | N11: =IFERROR(IF(F11="Active",INDEX('Benchmark Rate Card'!$B$2:$G$4,MATCH('Portfolio Data (Modified)'!D11,'Benchmark Rate Card'!$A$2:$A$4,0),MATCH('Portfolio Data (Modified)'!C11,'Benchmark Rate Card'!$B$1:$G$1,0)),""),"") -> 43 | O11: Beacon Software | P11: IT Services | Q11: =IF(F11="Active",ROUND(I11/E11,2),"") -> 40.21 | R11: =IF(F11="Active",_xlfn.IFS(Q11>N11,"Above Benchmark",Q11<=N11,"At/Below Benchmark"),"") -> At/Below Benchmark | S11: =IFERROR(IF(F11="Active",DATEDIF(TODAY(),H11,"m"),""),"Expired") -> 8 | T11: =IF(OR(S11<12,S11="Expired"),"Renewal Watch","") -> Renewal Watch | U11: =IFERROR(RANK(I11,$I$2:$I$28,0),"") -> 16 | V11: =IF(F11<>"Active","",_xlfn.IFS(S11="Expired","Urgent",S11<3,"Urgent",S11<12,"Watch",S11>=12,"OK")) -> Watch
A12: R011 | B12: Coral Street Plaza | C12: Bengaluru | D12: Retail | E12: 24000 | F12: Active | G12: 2024-01-05 | H12: 2028-01-04 | I12: 990000 | J12: =COUNTIFS($B$2:$B$28,B12,$C$2:$C$28,C12,$G$2:$G$28,G12) -> 1 | K12: =IFERROR(INDEX('City-State Lookup'!$B$2:$B$7,MATCH('Portfolio Data (Modified)'!C12,'City-State Lookup'!$A$2:$A$7,0)),"Not Mapped") -> Karnataka | L12: =IFERROR(INDEX('State-Region Lookup'!$B$2:$B$6,MATCH('Portfolio Data (Modified)'!K12,'State-Region Lookup'!$A$2:$A$6,0)),"Not Mapped") -> South | M12: =IF(F12<>"Active","",VLOOKUP(I12,'Rent Band Table'!$A$2:$B$5,2,TRUE)) -> Low | N12: =IFERROR(IF(F12="Active",INDEX('Benchmark Rate Card'!$B$2:$G$4,MATCH('Portfolio Data (Modified)'!D12,'Benchmark Rate Card'!$A$2:$A$4,0),MATCH('Portfolio Data (Modified)'!C12,'Benchmark Rate Card'!$B$1:$G$1,0)),""),"") -> 46 | O12: Urban Threads | P12: Fashion Retail | Q12: =IF(F12="Active",ROUND(I12/E12,2),"") -> 41.25 | R12: =IF(F12="Active",_xlfn.IFS(Q12>N12,"Above Benchmark",Q12<=N12,"At/Below Benchmark"),"") -> At/Below Benchmark | S12: =IFERROR(IF(F12="Active",DATEDIF(TODAY(),H12,"m"),""),"Expired") -> 15 | T12: =IF(OR(S12<12,S12="Expired"),"Renewal Watch","") | U12: =IFERROR(RANK(I12,$I$2:$I$28,0),"") -> 22 | V12: =IF(F12<>"Active","",_xlfn.IFS(S12="Expired","Urgent",S12<3,"Urgent",S12<12,"Watch",S12>=12,"OK")) -> OK
A13: R012 | B13: Coral Street Plaza | C13: Bengaluru | D13: Retail | E13: 24000 | F13: Vacant | J13: =COUNTIFS($B$2:$B$28,B13,$C$2:$C$28,C13,$G$2:$G$28,G13) -> 0 | K13: =IFERROR(INDEX('City-State Lookup'!$B$2:$B$7,MATCH('Portfolio Data (Modified)'!C13,'City-State Lookup'!$A$2:$A$7,0)),"Not Mapped") -> Karnataka | L13: =IFERROR(INDEX('State-Region Lookup'!$B$2:$B$6,MATCH('Portfolio Data (Modified)'!K13,'State-Region Lookup'!$A$2:$A$6,0)),"Not Mapped") -> South | M13: =IF(F13<>"Active","",VLOOKUP(I13,'Rent Band Table'!$A$2:$B$5,2,TRUE)) | N13: =IFERROR(IF(F13="Active",INDEX('Benchmark Rate Card'!$B$2:$G$4,MATCH('Portfolio Data (Modified)'!D13,'Benchmark Rate Card'!$A$2:$A$4,0),MATCH('Portfolio Data (Modified)'!C13,'Benchmark Rate Card'!$B$1:$G$1,0)),""),"") | Q13: =IF(F13="Active",ROUND(I13/E13,2),"") | R13: =IF(F13="Active",_xlfn.IFS(Q13>N13,"Above Benchmark",Q13<=N13,"At/Below Benchmark"),"") | S13: =IFERROR(IF(F13="Active",DATEDIF(TODAY(),H13,"m"),""),"Expired") | T13: =IF(OR(S13<12,S13="Expired"),"Renewal Watch","") | U13: =IFERROR(RANK(I13,$I$2:$I$28,0),"") | V13: =IF(F13<>"Active","",_xlfn.IFS(S13="Expired","Urgent",S13<3,"Urgent",S13<12,"Watch",S13>=12,"OK"))
A14: R013 | B14: Northgate Logistics Hub | C14: Delhi | D14: Industrial | E14: 112000 | F14: Active | G14: 2019-11-11 | H14: 2024-11-10 | I14: 2980000 | J14: =COUNTIFS($B$2:$B$28,B14,$C$2:$C$28,C14,$G$2:$G$28,G14) -> 2 | K14: =IFERROR(INDEX('City-State Lookup'!$B$2:$B$7,MATCH('Portfolio Data (Modified)'!C14,'City-State Lookup'!$A$2:$A$7,0)),"Not Mapped") -> Delhi NCR | L14: =IFERROR(INDEX('State-Region Lookup'!$B$2:$B$6,MATCH('Portfolio Data (Modified)'!K14,'State-Region Lookup'!$A$2:$A$6,0)),"Not Mapped") -> North | M14: =IF(F14<>"Active","",VLOOKUP(I14,'Rent Band Table'!$A$2:$B$5,2,TRUE)) -> High | N14: =IFERROR(IF(F14="Active",INDEX('Benchmark Rate Card'!$B$2:$G$4,MATCH('Portfolio Data (Modified)'!D14,'Benchmark Rate Card'!$A$2:$A$4,0),MATCH('Portfolio Data (Modified)'!C14,'Benchmark Rate Card'!$B$1:$G$1,0)),""),"") -> 26 | O14: SwiftCargo Movers | P14: Logistics | Q14: =IF(F14="Active",ROUND(I14/E14,2),"") -> 26.61 | R14: =IF(F14="Active",_xlfn.IFS(Q14>N14,"Above Benchmark",Q14<=N14,"At/Below Benchmark"),"") -> Above Benchmark | S14: =IFERROR(IF(F14="Active",DATEDIF(TODAY(),H14,"m"),""),"Expired") -> Expired | T14: =IF(OR(S14<12,S14="Expired"),"Renewal Watch","") -> Renewal Watch | U14: =IFERROR(RANK(I14,$I$2:$I$28,0),"") -> 5 | V14: =IF(F14<>"Active","",_xlfn.IFS(S14="Expired","Urgent",S14<3,"Urgent",S14<12,"Watch",S14>=12,"OK")) -> Urgent
A15: R014 | B15: Northgate Logistics Hub | C15: Delhi | D15: Industrial | E15: 112000 | F15: Active | G15: 2019-11-11 | H15: 2024-11-10 | I15: 2980000 | J15: =COUNTIFS($B$2:$B$28,B15,$C$2:$C$28,C15,$G$2:$G$28,G15) -> 2 | K15: =IFERROR(INDEX('City-State Lookup'!$B$2:$B$7,MATCH('Portfolio Data (Modified)'!C15,'City-State Lookup'!$A$2:$A$7,0)),"Not Mapped") -> Delhi NCR | L15: =IFERROR(INDEX('State-Region Lookup'!$B$2:$B$6,MATCH('Portfolio Data (Modified)'!K15,'State-Region Lookup'!$A$2:$A$6,0)),"Not Mapped") -> North | M15: =IF(F15<>"Active","",VLOOKUP(I15,'Rent Band Table'!$A$2:$B$5,2,TRUE)) -> High | N15: =IFERROR(IF(F15="Active",INDEX('Benchmark Rate Card'!$B$2:$G$4,MATCH('Portfolio Data (Modified)'!D15,'Benchmark Rate Card'!$A$2:$A$4,0),MATCH('Portfolio Data (Modified)'!C15,'Benchmark Rate Card'!$B$1:$G$1,0)),""),"") -> 26 | O15: SwiftCargo Movers | P15: Logistics | Q15: =IF(F15="Active",ROUND(I15/E15,2),"") -> 26.61 | R15: =IF(F15="Active",_xlfn.IFS(Q15>N15,"Above Benchmark",Q15<=N15,"At/Below Benchmark"),"") -> Above Benchmark | S15: =IFERROR(IF(F15="Active",DATEDIF(TODAY(),H15,"m"),""),"Expired") -> Expired | T15: =IF(OR(S15<12,S15="Expired"),"Renewal Watch","") -> Renewal Watch | U15: =IFERROR(RANK(I15,$I$2:$I$28,0),"") -> 5 | V15: =IF(F15<>"Active","",_xlfn.IFS(S15="Expired","Urgent",S15<3,"Urgent",S15<12,"Watch",S15>=12,"OK")) -> Urgent
A16: R015 | B16: Zenith IT Campus | C16: Hyderabad | D16: Office | E16: 81000 | F16: Active | G16: 2022-09-01 | H16: 2029-08-31 | I16: 3120000 | J16: =COUNTIFS($B$2:$B$28,B16,$C$2:$C$28,C16,$G$2:$G$28,G16) -> 2 | K16: =IFERROR(INDEX('City-State Lookup'!$B$2:$B$7,MATCH('Portfolio Data (Modified)'!C16,'City-State Lookup'!$A$2:$A$7,0)),"Not Mapped") -> Telangana | L16: =IFERROR(INDEX('State-Region Lookup'!$B$2:$B$6,MATCH('Portfolio Data (Modified)'!K16,'State-Region Lookup'!$A$2:$A$6,0)),"Not Mapped") -> South | M16: =IF(F16<>"Active","",VLOOKUP(I16,'Rent Band Table'!$A$2:$B$5,2,TRUE)) -> Premium | N16: =IFERROR(IF(F16="Active",INDEX('Benchmark Rate Card'!$B$2:$G$4,MATCH('Portfolio Data (Modified)'!D16,'Benchmark Rate Card'!$A$2:$A$4,0),MATCH('Portfolio Data (Modified)'!C16,'Benchmark Rate Card'!$B$1:$G$1,0)),""),"") -> 39 | O16: CoreStack Systems | P16: IT Services | Q16: =IF(F16="Active",ROUND(I16/E16,2),"") -> 38.52 | R16: =IF(F16="Active",_xlfn.IFS(Q16>N16,"Above Benchmark",Q16<=N16,"At/Below Benchmark"),"") -> At/Below Benchmark | S16: =IFERROR(IF(F16="Active",DATEDIF(TODAY(),H16,"m"),""),"Expired") -> 35 | T16: =IF(OR(S16<12,S16="Expired"),"Renewal Watch","") | U16: =IFERROR(RANK(I16,$I$2:$I$28,0),"") -> 3 | V16: =IF(F16<>"Active","",_xlfn.IFS(S16="Expired","Urgent",S16<3,"Urgent",S16<12,"Watch",S16>=12,"OK")) -> OK
A17: R016 | B17: Zenith IT Campus | C17: Hyderabad | D17: Office | E17: 81000 | F17: Active | G17: 2022-09-01 | H17: 2029-08-31 | I17: 3120000 | J17: =COUNTIFS($B$2:$B$28,B17,$C$2:$C$28,C17,$G$2:$G$28,G17) -> 2 | K17: =IFERROR(INDEX('City-State Lookup'!$B$2:$B$7,MATCH('Portfolio Data (Modified)'!C17,'City-State Lookup'!$A$2:$A$7,0)),"Not Mapped") -> Telangana | L17: =IFERROR(INDEX('State-Region Lookup'!$B$2:$B$6,MATCH('Portfolio Data (Modified)'!K17,'State-Region Lookup'!$A$2:$A$6,0)),"Not Mapped") -> South | M17: =IF(F17<>"Active","",VLOOKUP(I17,'Rent Band Table'!$A$2:$B$5,2,TRUE)) -> Premium | N17: =IFERROR(IF(F17="Active",INDEX('Benchmark Rate Card'!$B$2:$G$4,MATCH('Portfolio Data (Modified)'!D17,'Benchmark Rate Card'!$A$2:$A$4,0),MATCH('Portfolio Data (Modified)'!C17,'Benchmark Rate Card'!$B$1:$G$1,0)),""),"") -> 39 | O17: CoreStack Systems | P17: IT Services | Q17: =IF(F17="Active",ROUND(I17/E17,2),"") -> 38.52 | R17: =IF(F17="Active",_xlfn.IFS(Q17>N17,"Above Benchmark",Q17<=N17,"At/Below Benchmark"),"") -> At/Below Benchmark | S17: =IFERROR(IF(F17="Active",DATEDIF(TODAY(),H17,"m"),""),"Expired") -> 35 | T17: =IF(OR(S17<12,S17="Expired"),"Renewal Watch","") | U17: =IFERROR(RANK(I17,$I$2:$I$28,0),"") -> 3 | V17: =IF(F17<>"Active","",_xlfn.IFS(S17="Expired","Urgent",S17<3,"Urgent",S17<12,"Watch",S17>=12,"OK")) -> OK
A18: R017 | B18: Marina Bay Retail Court | C18: Chennai | D18: Retail | E18: 19500 | F18: Active | G18: 2024-04-18 | H18: 2027-01-17 | I18: 870000 | J18: =COUNTIFS($B$2:$B$28,B18,$C$2:$C$28,C18,$G$2:$G$28,G18) -> 2 | K18: =IFERROR(INDEX('City-State Lookup'!$B$2:$B$7,MATCH('Portfolio Data (Modified)'!C18,'City-State Lookup'!$A$2:$A$7,0)),"Not Mapped") -> Tamil Nadu | L18: =IFERROR(INDEX('State-Region Lookup'!$B$2:$B$6,MATCH('Portfolio Data (Modified)'!K18,'State-Region Lookup'!$A$2:$A$6,0)),"Not Mapped") -> South | M18: =IF(F18<>"Active","",VLOOKUP(I18,'Rent Band Table'!$A$2:$B$5,2,TRUE)) -> Low | N18: =IFERROR(IF(F18="Active",INDEX('Benchmark Rate Card'!$B$2:$G$4,MATCH('Portfolio Data (Modified)'!D18,'Benchmark Rate Card'!$A$2:$A$4,0),MATCH('Portfolio Data (Modified)'!C18,'Benchmark Rate Card'!$B$1:$G$1,0)),""),"") -> 47 | O18: Coastal Bites | P18: F&B | Q18: =IF(F18="Active",ROUND(I18/E18,2),"") -> 44.62 | R18: =IF(F18="Active",_xlfn.IFS(Q18>N18,"Above Benchmark",Q18<=N18,"At/Below Benchmark"),"") -> At/Below Benchmark | S18: =IFERROR(IF(F18="Active",DATEDIF(TODAY(),H18,"m"),""),"Expired") -> 3 | T18: =IF(OR(S18<12,S18="Expired"),"Renewal Watch","") -> Renewal Watch | U18: =IFERROR(RANK(I18,$I$2:$I$28,0),"") -> 23 | V18: =IF(F18<>"Active","",_xlfn.IFS(S18="Expired","Urgent",S18<3,"Urgent",S18<12,"Watch",S18>=12,"OK")) -> Watch
A19: R018 | B19: Marina Bay Retail Court | C19: Chennai | D19: Retail | E19: 19500 | F19: Active | G19: 2024-04-18 | H19: 2027-01-17 | I19: 870000 | J19: =COUNTIFS($B$2:$B$28,B19,$C$2:$C$28,C19,$G$2:$G$28,G19) -> 2 | K19: =IFERROR(INDEX('City-State Lookup'!$B$2:$B$7,MATCH('Portfolio Data (Modified)'!C19,'City-State Lookup'!$A$2:$A$7,0)),"Not Mapped") -> Tamil Nadu | L19: =IFERROR(INDEX('State-Region Lookup'!$B$2:$B$6,MATCH('Portfolio Data (Modified)'!K19,'State-Region Lookup'!$A$2:$A$6,0)),"Not Mapped") -> South | M19: =IF(F19<>"Active","",VLOOKUP(I19,'Rent Band Table'!$A$2:$B$5,2,TRUE)) -> Low | N19: =IFERROR(IF(F19="Active",INDEX('Benchmark Rate Card'!$B$2:$G$4,MATCH('Portfolio Data (Modified)'!D19,'Benchmark Rate Card'!$A$2:$A$4,0),MATCH('Portfolio Data (Modified)'!C19,'Benchmark Rate Card'!$B$1:$G$1,0)),""),"") -> 47 | O19: Coastal Bites | P19: F&B | Q19: =IF(F19="Active",ROUND(I19/E19,2),"") -> 44.62 | R19: =IF(F19="Active",_xlfn.IFS(Q19>N19,"Above Benchmark",Q19<=N19,"At/Below Benchmark"),"") -> At/Below Benchmark | S19: =IFERROR(IF(F19="Active",DATEDIF(TODAY(),H19,"m"),""),"Expired") -> 3 | T19: =IF(OR(S19<12,S19="Expired"),"Renewal Watch","") -> Renewal Watch | U19: =IFERROR(RANK(I19,$I$2:$I$28,0),"") -> 23 | V19: =IF(F19<>"Active","",_xlfn.IFS(S19="Expired","Urgent",S19<3,"Urgent",S19<12,"Watch",S19>=12,"OK")) -> Watch
A20: R019 | B20: Summit Business Center | C20: Pune | D20: Office | E20: 39000 | F20: Active | G20: 2022-02-14 | H20: 2026-11-13 | I20: 1560000 | J20: =COUNTIFS($B$2:$B$28,B20,$C$2:$C$28,C20,$G$2:$G$28,G20) -> 1 | K20: =IFERROR(INDEX('City-State Lookup'!$B$2:$B$7,MATCH('Portfolio Data (Modified)'!C20,'City-State Lookup'!$A$2:$A$7,0)),"Not Mapped") -> Maharashtra | L20: =IFERROR(INDEX('State-Region Lookup'!$B$2:$B$6,MATCH('Portfolio Data (Modified)'!K20,'State-Region Lookup'!$A$2:$A$6,0)),"Not Mapped") -> West | M20: =IF(F20<>"Active","",VLOOKUP(I20,'Rent Band Table'!$A$2:$B$5,2,TRUE)) -> Medium | N20: =IFERROR(IF(F20="Active",INDEX('Benchmark Rate Card'!$B$2:$G$4,MATCH('Portfolio Data (Modified)'!D20,'Benchmark Rate Card'!$A$2:$A$4,0),MATCH('Portfolio Data (Modified)'!C20,'Benchmark Rate Card'!$B$1:$G$1,0)),""),"") -> 43 | O20: Alpine Consulting | P20: Professional Services | Q20: =IF(F20="Active",ROUND(I20/E20,2),"") -> 40 | R20: =IF(F20="Active",_xlfn.IFS(Q20>N20,"Above Benchmark",Q20<=N20,"At/Below Benchmark"),"") -> At/Below Benchmark | S20: =IFERROR(IF(F20="Active",DATEDIF(TODAY(),H20,"m"),""),"Expired") -> 1 | T20: =IF(OR(S20<12,S20="Expired"),"Renewal Watch","") -> Renewal Watch | U20: =IFERROR(RANK(I20,$I$2:$I$28,0),"") -> 19 | V20: =IF(F20<>"Active","",_xlfn.IFS(S20="Expired","Urgent",S20<3,"Urgent",S20<12,"Watch",S20>=12,"OK")) -> Urgent
A21: R020 | B21: Summit Business Center | C21: Pune | D21: Office | E21: 39000 | F21: Vacant | J21: =COUNTIFS($B$2:$B$28,B21,$C$2:$C$28,C21,$G$2:$G$28,G21) -> 0 | K21: =IFERROR(INDEX('City-State Lookup'!$B$2:$B$7,MATCH('Portfolio Data (Modified)'!C21,'City-State Lookup'!$A$2:$A$7,0)),"Not Mapped") -> Maharashtra | L21: =IFERROR(INDEX('State-Region Lookup'!$B$2:$B$6,MATCH('Portfolio Data (Modified)'!K21,'State-Region Lookup'!$A$2:$A$6,0)),"Not Mapped") -> West | M21: =IF(F21<>"Active","",VLOOKUP(I21,'Rent Band Table'!$A$2:$B$5,2,TRUE)) | N21: =IFERROR(IF(F21="Active",INDEX('Benchmark Rate Card'!$B$2:$G$4,MATCH('Portfolio Data (Modified)'!D21,'Benchmark Rate Card'!$A$2:$A$4,0),MATCH('Portfolio Data (Modified)'!C21,'Benchmark Rate Card'!$B$1:$G$1,0)),""),"") | Q21: =IF(F21="Active",ROUND(I21/E21,2),"") | R21: =IF(F21="Active",_xlfn.IFS(Q21>N21,"Above Benchmark",Q21<=N21,"At/Below Benchmark"),"") | S21: =IFERROR(IF(F21="Active",DATEDIF(TODAY(),H21,"m"),""),"Expired") | T21: =IF(OR(S21<12,S21="Expired"),"Renewal Watch","") | U21: =IFERROR(RANK(I21,$I$2:$I$28,0),"") | V21: =IF(F21<>"Active","",_xlfn.IFS(S21="Expired","Urgent",S21<3,"Urgent",S21<12,"Watch",S21>=12,"OK"))
A22: R021 | B22: Blue Ridge Warehouse | C22: Mumbai | D22: Industrial | E22: 98000 | F22: Active | G22: 2021-07-07 | H22: 2028-07-06 | I22: 2450000 | J22: =COUNTIFS($B$2:$B$28,B22,$C$2:$C$28,C22,$G$2:$G$28,G22) -> 1 | K22: =IFERROR(INDEX('City-State Lookup'!$B$2:$B$7,MATCH('Portfolio Data (Modified)'!C22,'City-State Lookup'!$A$2:$A$7,0)),"Not Mapped") -> Maharashtra | L22: =IFERROR(INDEX('State-Region Lookup'!$B$2:$B$6,MATCH('Portfolio Data (Modified)'!K22,'State-Region Lookup'!$A$2:$A$6,0)),"Not Mapped") -> West | M22: =IF(F22<>"Active","",VLOOKUP(I22,'Rent Band Table'!$A$2:$B$5,2,TRUE)) -> High | N22: =IFERROR(IF(F22="Active",INDEX('Benchmark Rate Card'!$B$2:$G$4,MATCH('Portfolio Data (Modified)'!D22,'Benchmark Rate Card'!$A$2:$A$4,0),MATCH('Portfolio Data (Modified)'!C22,'Benchmark Rate Card'!$B$1:$G$1,0)),""),"") -> 28 | O22: Continental Freight | P22: Logistics | Q22: =IF(F22="Active",ROUND(I22/E22,2),"") -> 25 | R22: =IF(F22="Active",_xlfn.IFS(Q22>N22,"Above Benchmark",Q22<=N22,"At/Below Benchmark"),"") -> At/Below Benchmark | S22: =IFERROR(IF(F22="Active",DATEDIF(TODAY(),H22,"m"),""),"Expired") -> 21 | T22: =IF(OR(S22<12,S22="Expired"),"Renewal Watch","") | U22: =IFERROR(RANK(I22,$I$2:$I$28,0),"") -> 9 | V22: =IF(F22<>"Active","",_xlfn.IFS(S22="Expired","Urgent",S22<3,"Urgent",S22<12,"Watch",S22>=12,"OK")) -> OK
A23: R022 | B23: Ashoka Trade Center | C23: Noida | D23: Office | E23: 44000 | F23: Active | G23: 2023-10-01 | H23: 2027-04-30 | I23: 1780000 | J23: =COUNTIFS($B$2:$B$28,B23,$C$2:$C$28,C23,$G$2:$G$28,G23) -> 1 | K23: =IFERROR(INDEX('City-State Lookup'!$B$2:$B$7,MATCH('Portfolio Data (Modified)'!C23,'City-State Lookup'!$A$2:$A$7,0)),"Not Mapped") -> Not Mapped | L23: =IFERROR(INDEX('State-Region Lookup'!$B$2:$B$6,MATCH('Portfolio Data (Modified)'!K23,'State-Region Lookup'!$A$2:$A$6,0)),"Not Mapped") -> Not Mapped | M23: =IF(F23<>"Active","",VLOOKUP(I23,'Rent Band Table'!$A$2:$B$5,2,TRUE)) -> Medium | N23: =IFERROR(IF(F23="Active",INDEX('Benchmark Rate Card'!$B$2:$G$4,MATCH('Portfolio Data (Modified)'!D23,'Benchmark Rate Card'!$A$2:$A$4,0),MATCH('Portfolio Data (Modified)'!C23,'Benchmark Rate Card'!$B$1:$G$1,0)),""),"") | O23: Pioneer Traders | P23: Professional Services | Q23: =IF(F23="Active",ROUND(I23/E23,2),"") -> 40.45 | R23: =IF(F23="Active",_xlfn.IFS(Q23>N23,"Above Benchmark",Q23<=N23,"At/Below Benchmark"),"") -> At/Below Benchmark | S23: =IFERROR(IF(F23="Active",DATEDIF(TODAY(),H23,"m"),""),"Expired") -> 7 | T23: =IF(OR(S23<12,S23="Expired"),"Renewal Watch","") -> Renewal Watch | U23: =IFERROR(RANK(I23,$I$2:$I$28,0),"") -> 18 | V23: =IF(F23<>"Active","",_xlfn.IFS(S23="Expired","Urgent",S23<3,"Urgent",S23<12,"Watch",S23>=12,"OK")) -> Watch
A24: R023 | B24: Lotus Corporate Park | C24: Bengaluru | D24: Office | E24: 59000 | F24: Active | G24: 2020-12-01 | H24: 2026-10-30 | I24: 2340000 | J24: =COUNTIFS($B$2:$B$28,B24,$C$2:$C$28,C24,$G$2:$G$28,G24) -> 2 | K24: =IFERROR(INDEX('City-State Lookup'!$B$2:$B$7,MATCH('Portfolio Data (Modified)'!C24,'City-State Lookup'!$A$2:$A$7,0)),"Not Mapped") -> Karnataka | L24: =IFERROR(INDEX('State-Region Lookup'!$B$2:$B$6,MATCH('Portfolio Data (Modified)'!K24,'State-Region Lookup'!$A$2:$A$6,0)),"Not Mapped") -> South | M24: =IF(F24<>"Active","",VLOOKUP(I24,'Rent Band Table'!$A$2:$B$5,2,TRUE)) -> High | N24: =IFERROR(IF(F24="Active",INDEX('Benchmark Rate Card'!$B$2:$G$4,MATCH('Portfolio Data (Modified)'!D24,'Benchmark Rate Card'!$A$2:$A$4,0),MATCH('Portfolio Data (Modified)'!C24,'Benchmark Rate Card'!$B$1:$G$1,0)),""),"") -> 42 | O24: Vertex BioLabs | P24: Pharma | Q24: =IF(F24="Active",ROUND(I24/E24,2),"") -> 39.66 | R24: =IF(F24="Active",_xlfn.IFS(Q24>N24,"Above Benchmark",Q24<=N24,"At/Below Benchmark"),"") -> At/Below Benchmark | S24: =IFERROR(IF(F24="Active",DATEDIF(TODAY(),H24,"m"),""),"Expired") -> 1 | T24: =IF(OR(S24<12,S24="Expired"),"Renewal Watch","") -> Renewal Watch | U24: =IFERROR(RANK(I24,$I$2:$I$28,0),"") -> 10 | V24: =IF(F24<>"Active","",_xlfn.IFS(S24="Expired","Urgent",S24<3,"Urgent",S24<12,"Watch",S24>=12,"OK")) -> Urgent
A25: R024 | B25: Lotus Corporate Park | C25: Bengaluru | D25: Office | E25: 59000 | F25: Active | G25: 2020-12-01 | H25: 2026-10-30 | I25: 2340000 | J25: =COUNTIFS($B$2:$B$28,B25,$C$2:$C$28,C25,$G$2:$G$28,G25) -> 2 | K25: =IFERROR(INDEX('City-State Lookup'!$B$2:$B$7,MATCH('Portfolio Data (Modified)'!C25,'City-State Lookup'!$A$2:$A$7,0)),"Not Mapped") -> Karnataka | L25: =IFERROR(INDEX('State-Region Lookup'!$B$2:$B$6,MATCH('Portfolio Data (Modified)'!K25,'State-Region Lookup'!$A$2:$A$6,0)),"Not Mapped") -> South | M25: =IF(F25<>"Active","",VLOOKUP(I25,'Rent Band Table'!$A$2:$B$5,2,TRUE)) -> High | N25: =IFERROR(IF(F25="Active",INDEX('Benchmark Rate Card'!$B$2:$G$4,MATCH('Portfolio Data (Modified)'!D25,'Benchmark Rate Card'!$A$2:$A$4,0),MATCH('Portfolio Data (Modified)'!C25,'Benchmark Rate Card'!$B$1:$G$1,0)),""),"") -> 42 | O25: Vertex BioLabs | P25: Pharma | Q25: =IF(F25="Active",ROUND(I25/E25,2),"") -> 39.66 | R25: =IF(F25="Active",_xlfn.IFS(Q25>N25,"Above Benchmark",Q25<=N25,"At/Below Benchmark"),"") -> At/Below Benchmark | S25: =IFERROR(IF(F25="Active",DATEDIF(TODAY(),H25,"m"),""),"Expired") -> 1 | T25: =IF(OR(S25<12,S25="Expired"),"Renewal Watch","") -> Renewal Watch | U25: =IFERROR(RANK(I25,$I$2:$I$28,0),"") -> 10 | V25: =IF(F25<>"Active","",_xlfn.IFS(S25="Expired","Urgent",S25<3,"Urgent",S25<12,"Watch",S25>=12,"OK")) -> Urgent
A26: R025 | B26: Golden Harbor Mall | C26: Mumbai | D26: Retail | E26: 27500 | F26: Active | G26: 2023-08-20 | H26: 2029-08-19 | I26: 1180000 | J26: =COUNTIFS($B$2:$B$28,B26,$C$2:$C$28,C26,$G$2:$G$28,G26) -> 1 | K26: =IFERROR(INDEX('City-State Lookup'!$B$2:$B$7,MATCH('Portfolio Data (Modified)'!C26,'City-State Lookup'!$A$2:$A$7,0)),"Not Mapped") -> Maharashtra | L26: =IFERROR(INDEX('State-Region Lookup'!$B$2:$B$6,MATCH('Portfolio Data (Modified)'!K26,'State-Region Lookup'!$A$2:$A$6,0)),"Not Mapped") -> West | M26: =IF(F26<>"Active","",VLOOKUP(I26,'Rent Band Table'!$A$2:$B$5,2,TRUE)) -> Medium | N26: =IFERROR(IF(F26="Active",INDEX('Benchmark Rate Card'!$B$2:$G$4,MATCH('Portfolio Data (Modified)'!D26,'Benchmark Rate Card'!$A$2:$A$4,0),MATCH('Portfolio Data (Modified)'!C26,'Benchmark Rate Card'!$B$1:$G$1,0)),""),"") -> 58 | O26: Bay Fashion House | P26: Fashion Retail | Q26: =IF(F26="Active",ROUND(I26/E26,2),"") -> 42.91 | R26: =IF(F26="Active",_xlfn.IFS(Q26>N26,"Above Benchmark",Q26<=N26,"At/Below Benchmark"),"") -> At/Below Benchmark | S26: =IFERROR(IF(F26="Active",DATEDIF(TODAY(),H26,"m"),""),"Expired") -> 34 | T26: =IF(OR(S26<12,S26="Expired"),"Renewal Watch","") | U26: =IFERROR(RANK(I26,$I$2:$I$28,0),"") -> 21 | V26: =IF(F26<>"Active","",_xlfn.IFS(S26="Expired","Urgent",S26<3,"Urgent",S26<12,"Watch",S26>=12,"OK")) -> OK
A27: R026 | B27: Falcon Industrial Estate | C27: Chennai | D27: Industrial | E27: 87000 | F27: Active | G27: 2022-03-15 | H27: 2025-10-14 | I27: 2210000 | J27: =COUNTIFS($B$2:$B$28,B27,$C$2:$C$28,C27,$G$2:$G$28,G27) -> 2 | K27: =IFERROR(INDEX('City-State Lookup'!$B$2:$B$7,MATCH('Portfolio Data (Modified)'!C27,'City-State Lookup'!$A$2:$A$7,0)),"Not Mapped") -> Tamil Nadu | L27: =IFERROR(INDEX('State-Region Lookup'!$B$2:$B$6,MATCH('Portfolio Data (Modified)'!K27,'State-Region Lookup'!$A$2:$A$6,0)),"Not Mapped") -> South | M27: =IF(F27<>"Active","",VLOOKUP(I27,'Rent Band Table'!$A$2:$B$5,2,TRUE)) -> High | N27: =IFERROR(IF(F27="Active",INDEX('Benchmark Rate Card'!$B$2:$G$4,MATCH('Portfolio Data (Modified)'!D27,'Benchmark Rate Card'!$A$2:$A$4,0),MATCH('Portfolio Data (Modified)'!C27,'Benchmark Rate Card'!$B$1:$G$1,0)),""),"") -> 23 | O27: TransGlobal Logistics | P27: Logistics | Q27: =IF(F27="Active",ROUND(I27/E27,2),"") -> 25.4 | R27: =IF(F27="Active",_xlfn.IFS(Q27>N27,"Above Benchmark",Q27<=N27,"At/Below Benchmark"),"") -> Above Benchmark | S27: =IFERROR(IF(F27="Active",DATEDIF(TODAY(),H27,"m"),""),"Expired") -> Expired | T27: =IF(OR(S27<12,S27="Expired"),"Renewal Watch","") -> Renewal Watch | U27: =IFERROR(RANK(I27,$I$2:$I$28,0),"") -> 12 | V27: =IF(F27<>"Active","",_xlfn.IFS(S27="Expired","Urgent",S27<3,"Urgent",S27<12,"Watch",S27>=12,"OK")) -> Urgent
A28: R027 | B28: Falcon Industrial Estate | C28: Chennai | D28: Industrial | E28: 87000 | F28: Active | G28: 2022-03-15 | H28: 2025-10-14 | I28: 2210000 | J28: =COUNTIFS($B$2:$B$28,B28,$C$2:$C$28,C28,$G$2:$G$28,G28) -> 2 | K28: =IFERROR(INDEX('City-State Lookup'!$B$2:$B$7,MATCH('Portfolio Data (Modified)'!C28,'City-State Lookup'!$A$2:$A$7,0)),"Not Mapped") -> Tamil Nadu | L28: =IFERROR(INDEX('State-Region Lookup'!$B$2:$B$6,MATCH('Portfolio Data (Modified)'!K28,'State-Region Lookup'!$A$2:$A$6,0)),"Not Mapped") -> South | M28: =IF(F28<>"Active","",VLOOKUP(I28,'Rent Band Table'!$A$2:$B$5,2,TRUE)) -> High | N28: =IFERROR(IF(F28="Active",INDEX('Benchmark Rate Card'!$B$2:$G$4,MATCH('Portfolio Data (Modified)'!D28,'Benchmark Rate Card'!$A$2:$A$4,0),MATCH('Portfolio Data (Modified)'!C28,'Benchmark Rate Card'!$B$1:$G$1,0)),""),"") -> 23 | O28: TransGlobal Logistics | P28: Logistics | Q28: =IF(F28="Active",ROUND(I28/E28,2),"") -> 25.4 | R28: =IF(F28="Active",_xlfn.IFS(Q28>N28,"Above Benchmark",Q28<=N28,"At/Below Benchmark"),"") -> Above Benchmark | S28: =IFERROR(IF(F28="Active",DATEDIF(TODAY(),H28,"m"),""),"Expired") -> Expired | T28: =IF(OR(S28<12,S28="Expired"),"Renewal Watch","") -> Renewal Watch | U28: =IFERROR(RANK(I28,$I$2:$I$28,0),"") -> 12 | V28: =IF(F28<>"Active","",_xlfn.IFS(S28="Expired","Urgent",S28<3,"Urgent",S28<12,"Watch",S28>=12,"OK")) -> Urgent
A32: Largest active montly rent in each city and its property name
A33: City | B33: Property Name | C33: Rent
A34: Bengaluru | B34: =INDEX($B$2:$B$28,MATCH(C34,$I$2:$I$28,0)) -> Lotus Corporate Park | C34: =_xlfn.MAXIFS($I$2:$I$28,$C$2:$C$28,A34,$F$2:$F$28,"Active") -> 2340000
A35: Hyderabad | B35: =INDEX($B$2:$B$28,MATCH(C35,$I$2:$I$28,0)) -> Zenith IT Campus | C35: =_xlfn.MAXIFS($I$2:$I$28,$C$2:$C$28,A35,$F$2:$F$28,"Active") -> 3120000
A36: Chennai | B36: =INDEX($B$2:$B$28,MATCH(C36,$I$2:$I$28,0)) -> Falcon Industrial Estate | C36: =_xlfn.MAXIFS($I$2:$I$28,$C$2:$C$28,A36,$F$2:$F$28,"Active") -> 2210000
A37: Mumbai | B37: =INDEX($B$2:$B$28,MATCH(C37,$I$2:$I$28,0)) -> Anchor Point Warehouse | C37: =_xlfn.MAXIFS($I$2:$I$28,$C$2:$C$28,A37,$F$2:$F$28,"Active") -> 3550000
A38: Pune | B38: =INDEX($B$2:$B$28,MATCH(C38,$I$2:$I$28,0)) -> Silver Oak Tech Park | C38: =_xlfn.MAXIFS($I$2:$I$28,$C$2:$C$28,A38,$F$2:$F$28,"Active") -> 1890000
A39: Delhi | B39: =INDEX($B$2:$B$28,MATCH(C39,$I$2:$I$28,0)) -> Northgate Logistics Hub | C39: =_xlfn.MAXIFS($I$2:$I$28,$C$2:$C$28,A39,$F$2:$F$28,"Active") -> 2980000
A40: Noida | B40: =INDEX($B$2:$B$28,MATCH(C40,$I$2:$I$28,0)) -> Ashoka Trade Center | C40: =_xlfn.MAXIFS($I$2:$I$28,$C$2:$C$28,A40,$F$2:$F$28,"Active") -> 1780000
A42: distinct tenant industries | B42: =SUMPRODUCT((P2:P28<>"")/COUNTIF(P2:P28,P2:P28&"")) -> 6
A44: Total Rent by Region
A45: South | B45: =SUMIFS($I$2:$I$28,$L$2:$L$28,"South",$F$2:$F$28,"Active") -> 29050000
...

Sheet City-State Lookup
A1: City | B1: State
A2: Bengaluru | B2: Karnataka
A3: Hyderabad | B3: Telangana
A4: Chennai | B4: Tamil Nadu
A5: Mumbai | B5: Maharashtra
A6: Pune | B6: Maharashtra
A7: Delhi | B7: Delhi NCR

Sheet State-Region Lookup
A1: State | B1: Region
A2: Karnataka | B2: South
A3: Telangana | B3: South
A4: Tamil Nadu | B4: South
A5: Maharashtra | B5: West
A6: Delhi NCR | B6: North

Sheet Rent Band Table
A1: Monthly Rent From (INR) | B1: Band
A2: 0 | B2: Low
A3: 1000000 | B3: Medium
A4: 2000000 | B4: High
A5: 3000000 | B5: Premium

Sheet Benchmark Rate Card
A1: Property Type | B1: Bengaluru | C1: Hyderabad | D1: Chennai | E1: Mumbai | F1: Pune | G1: Delhi
A2: Office | B2: 42 | C2: 39 | D2: 41 | E2: 55 | F2: 43 | G2: 48
A3: Retail | B3: 46 | C3: 44 | D3: 47 | E3: 58 | F3: 45 | G3: 50
A4: Industrial | B4: 22 | C4: 20 | D4: 23 | E4: 28 | F4: 24 | G4: 26

Sheet Pivot Table
A1: Region | B1: (All)
A3: Property Type | B3: Average of Actual Rent per sqft
A4: Industrial | B4: 25.425714
A5: Office | B5: 39.895833
A6: Retail | B6: 43.196
A7: Grand Total | B7: 36.362917
