Workbook

Sheet Portfolio Data (Raw)
A1: Property ID | B1: Property Name | C1: City | D1: Property Type | E1: Total Area (sqft) | F1: Lease Status | G1: Tenant Name | H1: Tenant Industry | I1: Lease Start Date | J1: Lease End Date | K1: Monthly Rent (INR) | L1: Landlord Contact
A2: T001 | B2: Horizon Corporate Suites | C2: Bengaluru | D2: Office | E2: 49000 | F2: Active | G2: Pulse Robotics | H2: it services | I2: 2021-06-01 | J2: 2027-05-31 | K2: 1980000 | L2: Rajan Mehta
A3: T002 | B3: Horizon Corporate Suites | C3: Bengaluru | D3: Office | E3: 49000 | F3: Active | G3: Pulse Robotics | H3: IT Services | I3: 2021-06-01 | J3: 2027-05-31 | K3: 1980000 | L3: Rajan Mehta
A4: T003 | B4: Meridian Trade Tower | C4: hyderabad | D4: Office | E4: 73000 | F4: Active | G4: Orbit Financial Services | H4: finance | I4: 2020-02-10 | J4: 2028-02-09 | K4: 3050000 | L4: Kavya Rao
A5: T004 | B5: Meridian Trade Tower | C5: Hyderabad | D5: office | E5: 73000 | F5: active | G5: Orbit Financial Services | H5: Finance | I5: 2020-02-10 | J5: 2028-02-09 | K5: 3050000 | L5: Kavya Rao
A6: T005 | B6: Cedar Grove Outlet | C6: Chennai | D6: Retail | E6: 21000 | F6: Active | G6: Coastal Crafts | H6: retail trade | I6: 2023-09-01 | J6: 2025-08-31 | K6: 890000
A7: T006 | B7: Cedar Grove Outlet | C7: CHENNAI | D7: Retail | E7: 21000 | F7: Active | G7: Coastal Crafts | H7: Retail Trade | I7: 2023-09-01 | J7: 2025-08-31 | K7: 890000
A8: T007 | B8: Portside Storage Hub | C8: Mumbai | D8: Industrial | E8: 158000 | F8: Active | G8: Anchor Freight Co | H8: logistics | I8: 2019-04-15 | J8: 2029-04-14 | K8: 3980000 | L8: Imran Sheikh
A9: T008 | B9: Portside Storage Hub | C9: Mumbai | D9: Industrial | E9: 158000 | F9: Active | G9: Anchor Freight Co | H9: Logistics | I9: 2019-04-15 | J9: 2029-04-14 | K9: 3980000 | L9: Imran Sheikh
A10: T009 | B10: Willowbrook IT Park | C10: Pune | D10: Office | E10: 51000 | F10: Active | G10: Vertex Cloud Labs | H10: it services | I10: 2022-11-01 | J10: 2025-10-31 | K10: 2040000 | L10: Sneha Kulkarni
A11: T010 | B11: Willowbrook IT Park | C11: pune | D11: office | E11: 51000 | F11: Active | G11: Vertex Cloud Labs | H11: IT Services | I11: 2022-11-01 | J11: 2025-10-31 | K11: 2040000 | L11: Sneha Kulkarni
A12: T011 | B12: Clover Street Mall | C12: Bengaluru | D12: Retail | E12: 33000 | F12: Active | G12: Bloom Boutique | H12: fashion retail | I12: 2024-02-01 | J12: 2026-01-31 | K12: 1410000 | L12: Farhan Ali
A13: T012 | B13: Clover Street Mall | C13: Bengaluru | D13: Retail | E13: 33000 | F13: vacant | L13: Farhan Ali
A14: T013 | B14: Ironbridge Logistics Center | C14: Delhi | D14: Industrial | E14: 121000 | F14: Active | G14: Capital Movers | H14: logistics | I14: 2018-08-20 | J14: 2028-08-19 | K14: 3210000
A15: T014 | B15: Ironbridge Logistics Center | C15: Delhi | D15: industrial | E15: 121000 | F15: Active | G15: Capital Movers | H15: Logistics | I15: 2018-08-20 | J15: 2028-08-19 | K15: 3210000
A16: T015 | B16: Skyward Business Tower | C16: hyderabad | D16: Office | E16: 66000 | F16: Active | G16: Nova Insurance Group | H16: finance | I16: 2023-01-15 | J16: 2026-01-14 | K16: 2760000 | L16: Divya Reddy
A17: T016 | B17: Skyward Business Tower | C17: Hyderabad | D17: Office | E17: 66000 | F17: Active | G17: Nova Insurance Group | H17: Finance | I17: 2023-01-15 | J17: 2026-01-14 | K17: 2760000 | L17: Divya Reddy
A18: T017 | B18: Seabreeze Shopping Court | C18: Chennai | D18: Retail | E18: 17500 | F18: Active | G18: Palm Leaf Eatery | H18: food & beverage | I18: 2024-06-01 | J18: 2027-05-31 | K18: 760000 | L18: Ganesh Pillai
A19: T018 | B19: Seabreeze Shopping Court | C19: chennai | D19: retail | E19: 17500 | F19: Active | G19: Palm Leaf Eatery | H19: Food & Beverage | I19: 2024-06-01 | J19: 2027-05-31 | K19: 760000 | L19: Ganesh Pillai
A20: T019 | B20: Maple Ridge Office Complex | C20: Pune | D20: Office | E20: 44000 | F20: Active | G20: Ledger & Co Advisory | H20: professional services | I20: 2021-05-10 | J20: 2024-05-09 | K20: 1720000
A21: T020 | B21: Maple Ridge Office Complex | C21: Pune | D21: Office | E21: 44000 | F21: vacant
A22: T021 | B22: Harborline Distribution Center | C22: Mumbai | D22: Industrial | E22: 132000 | F22: Active | G22: Continental Cargo | H22: logistics | I22: 2022-03-01 | J22: 2030-02-28 | K22: 3420000 | L22: Priya Nair
A23: T022 | B23: Crown Point Plaza | C23: Delhi | D23: Office | E23: 58000 | F23: Active | G23: Summit Legal Partners | H23: professional services | I23: 2020-09-01 | J23: 2026-08-31 | K23: 2530000 | L23: Anand Verma
A24: T023 | B24: Crown Point Plaza | C24: Delhi | D24: Office | E24: 58000 | F24: Active | G24: Summit Legal Partners | H24: Professional Services | I24: 2020-09-01 | J24: 2026-08-31 | K24: 2530000 | L24: Anand Verma

Sheet Portfolio Data (Modified)
A1: Property ID | B1: Property Name | C1: City | D1: Property Type | E1: Total Area (sqft) | F1: Lease Status | G1: Tenant Name | H1: Tenant Industry | I1: Lease Start Date | J1: Lease End Date | K1: Monthly Rent (INR) | L1: Landlord Contact | M1: Monthly Rent (USD) | N1: Annual Rent (INR) | O1: Annual Rent (USD) | P1: Lease Term(Years) | Q1: Lease Term | R1: Flag of Avg of Total area | S1: Rent per sqft | T1: Premium Account | U1: Year
A2: T001 | B2: Horizon Corporate Suites | C2: Bengaluru | D2: Office | E2: 49000 | F2: Active | G2: Pulse Robotics | H2: It Services | I2: 2021-06-01 | J2: 2027-05-31 | K2: 1980000 | L2: Rajan Mehta | M2: =IF(F2<>"Active","",K2/'FX Rate Table'!$B$2) -> 23712.575 | N2: =IF(F2<>"Active","",K2*12) -> 23760000 | O2: =IF(F2<>"Active","",M2*12) -> 284550.9 | P2: =IF(F2="Active",DATEDIF(I2,J2,"y"),"") -> 5 | Q2: =IF(F2="Active",_xlfn.IFS(P2<3,"Short-Term",P2>=3,"Long-Term"),"") -> Long-Term | R2: =IF(AND(F2="Active",E2>$B$30),"Above Average Size","") | S2: =IF(F2="Active",ROUND(K2/E2,2),"") -> 40.41 | T2: =_xlfn.IFS(AND(F2="Active",K2>=_xlfn.PERCENTILE.INC($K$2:$K$24,75%)),"Premium Account",F2="Vacant","",AND(F2="Active",K2<_xlfn.PERCENTILE.INC($K$2:$K$24,75%)),"Standard") -> Standard | U2: =IF(F2="Active",YEAR(I2),"") -> 2021
A3: T002 | B3: Horizon Corporate Suites | C3: Bengaluru | D3: Office | E3: 49000 | F3: Active | G3: Pulse Robotics | H3: It Services | I3: 2021-06-01 | J3: 2027-05-31 | K3: 1980000 | L3: Rajan Mehta | M3: =IF(F3<>"Active","",K3/'FX Rate Table'!$B$2) -> 23712.575 | N3: =IF(F3<>"Active","",K3*12) -> 23760000 | O3: =IF(F3<>"Active","",M3*12) -> 284550.9 | P3: =IF(F3="Active",DATEDIF(I3,J3,"y"),"") -> 5 | Q3: =IF(F3="Active",_xlfn.IFS(P3<3,"Short-Term",P3>=3,"Long-Term"),"") -> Long-Term | R3: =IF(AND(F3="Active",E3>$B$30),"Above Average Size","") | S3: =IF(F3="Active",ROUND(K3/E3,2),"") -> 40.41 | T3: =_xlfn.IFS(AND(F3="Active",K3>=_xlfn.PERCENTILE.INC($K$2:$K$24,75%)),"Premium Account",F3="Vacant","",AND(F3="Active",K3<_xlfn.PERCENTILE.INC($K$2:$K$24,75%)),"Standard") -> Standard | U3: =IF(F3="Active",YEAR(I3),"") -> 2021
A4: T003 | B4: Meridian Trade Tower | C4: Hyderabad | D4: Office | E4: 73000 | F4: Active | G4: Orbit Financial Services | H4: Finance | I4: 2020-02-10 | J4: 2028-02-09 | K4: 3050000 | L4: Kavya Rao | M4: =IF(F4<>"Active","",K4/'FX Rate Table'!$B$2) -> 36526.946 | N4: =IF(F4<>"Active","",K4*12) -> 36600000 | O4: =IF(F4<>"Active","",M4*12) -> 438323.35 | P4: =IF(F4="Active",DATEDIF(I4,J4,"y"),"") -> 7 | Q4: =IF(F4="Active",_xlfn.IFS(P4<3,"Short-Term",P4>=3,"Long-Term"),"") -> Long-Term | R4: =IF(AND(F4="Active",E4>$B$30),"Above Average Size","") -> Above Average Size | S4: =IF(F4="Active",ROUND(K4/E4,2),"") -> 41.78 | T4: =_xlfn.IFS(AND(F4="Active",K4>=_xlfn.PERCENTILE.INC($K$2:$K$24,75%)),"Premium Account",F4="Vacant","",AND(F4="Active",K4<_xlfn.PERCENTILE.INC($K$2:$K$24,75%)),"Standard") -> Premium Account | U4: =IF(F4="Active",YEAR(I4),"") -> 2020
A5: T004 | B5: Meridian Trade Tower | C5: Hyderabad | D5: Office | E5: 73000 | F5: Active | G5: Orbit Financial Services | H5: Finance | I5: 2020-02-10 | J5: 2028-02-09 | K5: 3050000 | L5: Kavya Rao | M5: =IF(F5<>"Active","",K5/'FX Rate Table'!$B$2) -> 36526.946 | N5: =IF(F5<>"Active","",K5*12) -> 36600000 | O5: =IF(F5<>"Active","",M5*12) -> 438323.35 | P5: =IF(F5="Active",DATEDIF(I5,J5,"y"),"") -> 7 | Q5: =IF(F5="Active",_xlfn.IFS(P5<3,"Short-Term",P5>=3,"Long-Term"),"") -> Long-Term | R5: =IF(AND(F5="Active",E5>$B$30),"Above Average Size","") -> Above Average Size | S5: =IF(F5="Active",ROUND(K5/E5,2),"") -> 41.78 | T5: =_xlfn.IFS(AND(F5="Active",K5>=_xlfn.PERCENTILE.INC($K$2:$K$24,75%)),"Premium Account",F5="Vacant","",AND(F5="Active",K5<_xlfn.PERCENTILE.INC($K$2:$K$24,75%)),"Standard") -> Premium Account | U5: =IF(F5="Active",YEAR(I5),"") -> 2020
A6: T005 | B6: Cedar Grove Outlet | C6: Chennai | D6: Retail | E6: 21000 | F6: Active | G6: Coastal Crafts | H6: Retail Trade | I6: 2023-09-01 | J6: 2025-08-31 | K6: 890000 | M6: =IF(F6<>"Active","",K6/'FX Rate Table'!$B$2) -> 10658.683 | N6: =IF(F6<>"Active","",K6*12) -> 10680000 | O6: =IF(F6<>"Active","",M6*12) -> 127904.19 | P6: =IF(F6="Active",DATEDIF(I6,J6,"y"),"") -> 1 | Q6: =IF(F6="Active",_xlfn.IFS(P6<3,"Short-Term",P6>=3,"Long-Term"),"") -> Short-Term | R6: =IF(AND(F6="Active",E6>$B$30),"Above Average Size","") | S6: =IF(F6="Active",ROUND(K6/E6,2),"") -> 42.38 | T6: =_xlfn.IFS(AND(F6="Active",K6>=_xlfn.PERCENTILE.INC($K$2:$K$24,75%)),"Premium Account",F6="Vacant","",AND(F6="Active",K6<_xlfn.PERCENTILE.INC($K$2:$K$24,75%)),"Standard") -> Standard | U6: =IF(F6="Active",YEAR(I6),"") -> 2023
A7: T006 | B7: Cedar Grove Outlet | C7: Chennai | D7: Retail | E7: 21000 | F7: Active | G7: Coastal Crafts | H7: Retail Trade | I7: 2023-09-01 | J7: 2025-08-31 | K7: 890000 | M7: =IF(F7<>"Active","",K7/'FX Rate Table'!$B$2) -> 10658.683 | N7: =IF(F7<>"Active","",K7*12) -> 10680000 | O7: =IF(F7<>"Active","",M7*12) -> 127904.19 | P7: =IF(F7="Active",DATEDIF(I7,J7,"y"),"") -> 1 | Q7: =IF(F7="Active",_xlfn.IFS(P7<3,"Short-Term",P7>=3,"Long-Term"),"") -> Short-Term | R7: =IF(AND(F7="Active",E7>$B$30),"Above Average Size","") | S7: =IF(F7="Active",ROUND(K7/E7,2),"") -> 42.38 | T7: =_xlfn.IFS(AND(F7="Active",K7>=_xlfn.PERCENTILE.INC($K$2:$K$24,75%)),"Premium Account",F7="Vacant","",AND(F7="Active",K7<_xlfn.PERCENTILE.INC($K$2:$K$24,75%)),"Standard") -> Standard | U7: =IF(F7="Active",YEAR(I7),"") -> 2023
A8: T007 | B8: Portside Storage Hub | C8: Mumbai | D8: Industrial | E8: 158000 | F8: Active | G8: Anchor Freight Co | H8: Logistics | I8: 2019-04-15 | J8: 2029-04-14 | K8: 3980000 | L8: Imran Sheikh | M8: =IF(F8<>"Active","",K8/'FX Rate Table'!$B$2) -> 47664.671 | N8: =IF(F8<>"Active","",K8*12) -> 47760000 | O8: =IF(F8<>"Active","",M8*12) -> 571976.05 | P8: =IF(F8="Active",DATEDIF(I8,J8,"y"),"") -> 9 | Q8: =IF(F8="Active",_xlfn.IFS(P8<3,"Short-Term",P8>=3,"Long-Term"),"") -> Long-Term | R8: =IF(AND(F8="Active",E8>$B$30),"Above Average Size","") -> Above Average Size | S8: =IF(F8="Active",ROUND(K8/E8,2),"") -> 25.19 | T8: =_xlfn.IFS(AND(F8="Active",K8>=_xlfn.PERCENTILE.INC($K$2:$K$24,75%)),"Premium Account",F8="Vacant","",AND(F8="Active",K8<_xlfn.PERCENTILE.INC($K$2:$K$24,75%)),"Standard") -> Premium Account | U8: =IF(F8="Active",YEAR(I8),"") -> 2019
A9: T008 | B9: Portside Storage Hub | C9: Mumbai | D9: Industrial | E9: 158000 | F9: Active | G9: Anchor Freight Co | H9: Logistics | I9: 2019-04-15 | J9: 2029-04-14 | K9: 3980000 | L9: Imran Sheikh | M9: =IF(F9<>"Active","",K9/'FX Rate Table'!$B$2) -> 47664.671 | N9: =IF(F9<>"Active","",K9*12) -> 47760000 | O9: =IF(F9<>"Active","",M9*12) -> 571976.05 | P9: =IF(F9="Active",DATEDIF(I9,J9,"y"),"") -> 9 | Q9: =IF(F9="Active",_xlfn.IFS(P9<3,"Short-Term",P9>=3,"Long-Term"),"") -> Long-Term | R9: =IF(AND(F9="Active",E9>$B$30),"Above Average Size","") -> Above Average Size | S9: =IF(F9="Active",ROUND(K9/E9,2),"") -> 25.19 | T9: =_xlfn.IFS(AND(F9="Active",K9>=_xlfn.PERCENTILE.INC($K$2:$K$24,75%)),"Premium Account",F9="Vacant","",AND(F9="Active",K9<_xlfn.PERCENTILE.INC($K$2:$K$24,75%)),"Standard") -> Premium Account | U9: =IF(F9="Active",YEAR(I9),"") -> 2019
A10: T009 | B10: Willowbrook IT Park | C10: Pune | D10: Office | E10: 51000 | F10: Active | G10: Vertex Cloud Labs | H10: It Services | I10: 2022-11-01 | J10: 2025-10-31 | K10: 2040000 | L10: Sneha Kulkarni | M10: =IF(F10<>"Active","",K10/'FX Rate Table'!$B$2) -> 24431.138 | N10: =IF(F10<>"Active","",K10*12) -> 24480000 | O10: =IF(F10<>"Active","",M10*12) -> 293173.65 | P10: =IF(F10="Active",DATEDIF(I10,J10,"y"),"") -> 2 | Q10: =IF(F10="Active",_xlfn.IFS(P10<3,"Short-Term",P10>=3,"Long-Term"),"") -> Short-Term | R10: =IF(AND(F10="Active",E10>$B$30),"Above Average Size","") | S10: =IF(F10="Active",ROUND(K10/E10,2),"") -> 40 | T10: =_xlfn.IFS(AND(F10="Active",K10>=_xlfn.PERCENTILE.INC($K$2:$K$24,75%)),"Premium Account",F10="Vacant","",AND(F10="Active",K10<_xlfn.PERCENTILE.INC($K$2:$K$24,75%)),"Standard") -> Standard | U10: =IF(F10="Active",YEAR(I10),"") -> 2022
A11: T010 | B11: Willowbrook IT Park | C11: Pune | D11: Office | E11: 51000 | F11: Active | G11: Vertex Cloud Labs | H11: It Services | I11: 2022-11-01 | J11: 2025-10-31 | K11: 2040000 | L11: Sneha Kulkarni | M11: =IF(F11<>"Active","",K11/'FX Rate Table'!$B$2) -> 24431.138 | N11: =IF(F11<>"Active","",K11*12) -> 24480000 | O11: =IF(F11<>"Active","",M11*12) -> 293173.65 | P11: =IF(F11="Active",DATEDIF(I11,J11,"y"),"") -> 2 | Q11: =IF(F11="Active",_xlfn.IFS(P11<3,"Short-Term",P11>=3,"Long-Term"),"") -> Short-Term | R11: =IF(AND(F11="Active",E11>$B$30),"Above Average Size","") | S11: =IF(F11="Active",ROUND(K11/E11,2),"") -> 40 | T11: =_xlfn.IFS(AND(F11="Active",K11>=_xlfn.PERCENTILE.INC($K$2:$K$24,75%)),"Premium Account",F11="Vacant","",AND(F11="Active",K11<_xlfn.PERCENTILE.INC($K$2:$K$24,75%)),"Standard") -> Standard | U11: =IF(F11="Active",YEAR(I11),"") -> 2022
A12: T011 | B12: Clover Street Mall | C12: Bengaluru | D12: Retail | E12: 33000 | F12: Active | G12: Bloom Boutique | H12: Fashion Retail | I12: 2024-02-01 | J12: 2026-01-31 | K12: 1410000 | L12: Farhan Ali | M12: =IF(F12<>"Active","",K12/'FX Rate Table'!$B$2) -> 16886.228 | N12: =IF(F12<>"Active","",K12*12) -> 16920000 | O12: =IF(F12<>"Active","",M12*12) -> 202634.73 | P12: =IF(F12="Active",DATEDIF(I12,J12,"y"),"") -> 1 | Q12: =IF(F12="Active",_xlfn.IFS(P12<3,"Short-Term",P12>=3,"Long-Term"),"") -> Short-Term | R12: =IF(AND(F12="Active",E12>$B$30),"Above Average Size","") | S12: =IF(F12="Active",ROUND(K12/E12,2),"") -> 42.73 | T12: =_xlfn.IFS(AND(F12="Active",K12>=_xlfn.PERCENTILE.INC($K$2:$K$24,75%)),"Premium Account",F12="Vacant","",AND(F12="Active",K12<_xlfn.PERCENTILE.INC($K$2:$K$24,75%)),"Standard") -> Standard | U12: =IF(F12="Active",YEAR(I12),"") -> 2024
A13: T012 | B13: Clover Street Mall | C13: Bengaluru | D13: Retail | E13: 33000 | F13: Vacant | L13: Farhan Ali | M13: =IF(F13<>"Active","",K13/'FX Rate Table'!$B$2) | N13: =IF(F13<>"Active","",K13*12) | O13: =IF(F13<>"Active","",M13*12) | P13: =IF(F13="Active",DATEDIF(I13,J13,"y"),"") | Q13: =IF(F13="Active",_xlfn.IFS(P13<3,"Short-Term",P13>=3,"Long-Term"),"") | R13: =IF(AND(F13="Active",E13>$B$30),"Above Average Size","") | S13: =IF(F13="Active",ROUND(K13/E13,2),"") | T13: =_xlfn.IFS(AND(F13="Active",K13>=_xlfn.PERCENTILE.INC($K$2:$K$24,75%)),"Premium Account",F13="Vacant","",AND(F13="Active",K13<_xlfn.PERCENTILE.INC($K$2:$K$24,75%)),"Standard") | U13: =IF(F13="Active",YEAR(I13),"")
A14: T013 | B14: Ironbridge Logistics Center | C14: Delhi | D14: Industrial | E14: 121000 | F14: Active | G14: Capital Movers | H14: Logistics | I14: 2018-08-20 | J14: 2028-08-19 | K14: 3210000 | M14: =IF(F14<>"Active","",K14/'FX Rate Table'!$B$2) -> 38443.114 | N14: =IF(F14<>"Active","",K14*12) -> 38520000 | O14: =IF(F14<>"Active","",M14*12) -> 461317.37 | P14: =IF(F14="Active",DATEDIF(I14,J14,"y"),"") -> 9 | Q14: =IF(F14="Active",_xlfn.IFS(P14<3,"Short-Term",P14>=3,"Long-Term"),"") -> Long-Term | R14: =IF(AND(F14="Active",E14>$B$30),"Above Average Size","") -> Above Average Size | S14: =IF(F14="Active",ROUND(K14/E14,2),"") -> 26.53 | T14: =_xlfn.IFS(AND(F14="Active",K14>=_xlfn.PERCENTILE.INC($K$2:$K$24,75%)),"Premium Account",F14="Vacant","",AND(F14="Active",K14<_xlfn.PERCENTILE.INC($K$2:$K$24,75%)),"Standard") -> Premium Account | U14: =IF(F14="Active",YEAR(I14),"") -> 2018
A15: T014 | B15: Ironbridge Logistics Center | C15: Delhi | D15: Industrial | E15: 121000 | F15: Active | G15: Capital Movers | H15: Logistics | I15: 2018-08-20 | J15: 2028-08-19 | K15: 3210000 | M15: =IF(F15<>"Active","",K15/'FX Rate Table'!$B$2) -> 38443.114 | N15: =IF(F15<>"Active","",K15*12) -> 38520000 | O15: =IF(F15<>"Active","",M15*12) -> 461317.37 | P15: =IF(F15="Active",DATEDIF(I15,J15,"y"),"") -> 9 | Q15: =IF(F15="Active",_xlfn.IFS(P15<3,"Short-Term",P15>=3,"Long-Term"),"") -> Long-Term | R15: =IF(AND(F15="Active",E15>$B$30),"Above Average Size","") -> Above Average Size | S15: =IF(F15="Active",ROUND(K15/E15,2),"") -> 26.53 | T15: =_xlfn.IFS(AND(F15="Active",K15>=_xlfn.PERCENTILE.INC($K$2:$K$24,75%)),"Premium Account",F15="Vacant","",AND(F15="Active",K15<_xlfn.PERCENTILE.INC($K$2:$K$24,75%)),"Standard") -> Premium Account | U15: =IF(F15="Active",YEAR(I15),"") -> 2018
A16: T015 | B16: Skyward Business Tower | C16: Hyderabad | D16: Office | E16: 66000 | F16: Active | G16: Nova Insurance Group | H16: Finance | I16: 2023-01-15 | J16: 2026-01-14 | K16: 2760000 | L16: Divya Reddy | M16: =IF(F16<>"Active","",K16/'FX Rate Table'!$B$2) -> 33053.892 | N16: =IF(F16<>"Active","",K16*12) -> 33120000 | O16: =IF(F16<>"Active","",M16*12) -> 396646.71 | P16: =IF(F16="Active",DATEDIF(I16,J16,"y"),"") -> 2 | Q16: =IF(F16="Active",_xlfn.IFS(P16<3,"Short-Term",P16>=3,"Long-Term"),"") -> Short-Term | R16: =IF(AND(F16="Active",E16>$B$30),"Above Average Size","") | S16: =IF(F16="Active",ROUND(K16/E16,2),"") -> 41.82 | T16: =_xlfn.IFS(AND(F16="Active",K16>=_xlfn.PERCENTILE.INC($K$2:$K$24,75%)),"Premium Account",F16="Vacant","",AND(F16="Active",K16<_xlfn.PERCENTILE.INC($K$2:$K$24,75%)),"Standard") -> Standard | U16: =IF(F16="Active",YEAR(I16),"") -> 2023
A17: T016 | B17: Skyward Business Tower | C17: Hyderabad | D17: Office | E17: 66000 | F17: Active | G17: Nova Insurance Group | H17: Finance | I17: 2023-01-15 | J17: 2026-01-14 | K17: 2760000 | L17: Divya Reddy | M17: =IF(F17<>"Active","",K17/'FX Rate Table'!$B$2) -> 33053.892 | N17: =IF(F17<>"Active","",K17*12) -> 33120000 | O17: =IF(F17<>"Active","",M17*12) -> 396646.71 | P17: =IF(F17="Active",DATEDIF(I17,J17,"y"),"") -> 2 | Q17: =IF(F17="Active",_xlfn.IFS(P17<3,"Short-Term",P17>=3,"Long-Term"),"") -> Short-Term | R17: =IF(AND(F17="Active",E17>$B$30),"Above Average Size","") | S17: =IF(F17="Active",ROUND(K17/E17,2),"") -> 41.82 | T17: =_xlfn.IFS(AND(F17="Active",K17>=_xlfn.PERCENTILE.INC($K$2:$K$24,75%)),"Premium Account",F17="Vacant","",AND(F17="Active",K17<_xlfn.PERCENTILE.INC($K$2:$K$24,75%)),"Standard") -> Standard | U17: =IF(F17="Active",YEAR(I17),"") -> 2023
A18: T017 | B18: Seabreeze Shopping Court | C18: Chennai | D18: Retail | E18: 17500 | F18: Active | G18: Palm Leaf Eatery | H18: Food & Beverage | I18: 2024-06-01 | J18: 2027-05-31 | K18: 760000 | L18: Ganesh Pillai | M18: =IF(F18<>"Active","",K18/'FX Rate Table'!$B$2) -> 9101.7964 | N18: =IF(F18<>"Active","",K18*12) -> 9120000 | O18: =IF(F18<>"Active","",M18*12) -> 109221.56 | P18: =IF(F18="Active",DATEDIF(I18,J18,"y"),"") -> 2 | Q18: =IF(F18="Active",_xlfn.IFS(P18<3,"Short-Term",P18>=3,"Long-Term"),"") -> Short-Term | R18: =IF(AND(F18="Active",E18>$B$30),"Above Average Size","") | S18: =IF(F18="Active",ROUND(K18/E18,2),"") -> 43.43 | T18: =_xlfn.IFS(AND(F18="Active",K18>=_xlfn.PERCENTILE.INC($K$2:$K$24,75%)),"Premium Account",F18="Vacant","",AND(F18="Active",K18<_xlfn.PERCENTILE.INC($K$2:$K$24,75%)),"Standard") -> Standard | U18: =IF(F18="Active",YEAR(I18),"") -> 2024
A19: T018 | B19: Seabreeze Shopping Court | C19: Chennai | D19: Retail | E19: 17500 | F19: Active | G19: Palm Leaf Eatery | H19: Food & Beverage | I19: 2024-06-01 | J19: 2027-05-31 | K19: 760000 | L19: Ganesh Pillai | M19: =IF(F19<>"Active","",K19/'FX Rate Table'!$B$2) -> 9101.7964 | N19: =IF(F19<>"Active","",K19*12) -> 9120000 | O19: =IF(F19<>"Active","",M19*12) -> 109221.56 | P19: =IF(F19="Active",DATEDIF(I19,J19,"y"),"") -> 2 | Q19: =IF(F19="Active",_xlfn.IFS(P19<3,"Short-Term",P19>=3,"Long-Term"),"") -> Short-Term | R19: =IF(AND(F19="Active",E19>$B$30),"Above Average Size","") | S19: =IF(F19="Active",ROUND(K19/E19,2),"") -> 43.43 | T19: =_xlfn.IFS(AND(F19="Active",K19>=_xlfn.PERCENTILE.INC($K$2:$K$24,75%)),"Premium Account",F19="Vacant","",AND(F19="Active",K19<_xlfn.PERCENTILE.INC($K$2:$K$24,75%)),"Standard") -> Standard | U19: =IF(F19="Active",YEAR(I19),"") -> 2024
A20: T019 | B20: Maple Ridge Office Complex | C20: Pune | D20: Office | E20: 44000 | F20: Active | G20: Ledger & Co Advisory | H20: Professional Services | I20: 2021-05-10 | J20: 2024-05-09 | K20: 1720000 | M20: =IF(F20<>"Active","",K20/'FX Rate Table'!$B$2) -> 20598.802 | N20: =IF(F20<>"Active","",K20*12) -> 20640000 | O20: =IF(F20<>"Active","",M20*12) -> 247185.63 | P20: =IF(F20="Active",DATEDIF(I20,J20,"y"),"") -> 2 | Q20: =IF(F20="Active",_xlfn.IFS(P20<3,"Short-Term",P20>=3,"Long-Term"),"") -> Short-Term | R20: =IF(AND(F20="Active",E20>$B$30),"Above Average Size","") | S20: =IF(F20="Active",ROUND(K20/E20,2),"") -> 39.09 | T20: =_xlfn.IFS(AND(F20="Active",K20>=_xlfn.PERCENTILE.INC($K$2:$K$24,75%)),"Premium Account",F20="Vacant","",AND(F20="Active",K20<_xlfn.PERCENTILE.INC($K$2:$K$24,75%)),"Standard") -> Standard | U20: =IF(F20="Active",YEAR(I20),"") -> 2021
A21: T020 | B21: Maple Ridge Office Complex | C21: Pune | D21: Office | E21: 44000 | F21: Vacant | M21: =IF(F21<>"Active","",K21/'FX Rate Table'!$B$2) | N21: =IF(F21<>"Active","",K21*12) | O21: =IF(F21<>"Active","",M21*12) | P21: =IF(F21="Active",DATEDIF(I21,J21,"y"),"") | Q21: =IF(F21="Active",_xlfn.IFS(P21<3,"Short-Term",P21>=3,"Long-Term"),"") | R21: =IF(AND(F21="Active",E21>$B$30),"Above Average Size","") | S21: =IF(F21="Active",ROUND(K21/E21,2),"") | T21: =_xlfn.IFS(AND(F21="Active",K21>=_xlfn.PERCENTILE.INC($K$2:$K$24,75%)),"Premium Account",F21="Vacant","",AND(F21="Active",K21<_xlfn.PERCENTILE.INC($K$2:$K$24,75%)),"Standard") | U21: =IF(F21="Active",YEAR(I21),"")
A22: T021 | B22: Harborline Distribution Center | C22: Mumbai | D22: Industrial | E22: 132000 | F22: Active | G22: Continental Cargo | H22: Logistics | I22: 2022-03-01 | J22: 2030-02-28 | K22: 3420000 | L22: Priya Nair | M22: =IF(F22<>"Active","",K22/'FX Rate Table'!$B$2) -> 40958.084 | N22: =IF(F22<>"Active","",K22*12) -> 41040000 | O22: =IF(F22<>"Active","",M22*12) -> 491497.01 | P22: =IF(F22="Active",DATEDIF(I22,J22,"y"),"") -> 7 | Q22: =IF(F22="Active",_xlfn.IFS(P22<3,"Short-Term",P22>=3,"Long-Term"),"") -> Long-Term | R22: =IF(AND(F22="Active",E22>$B$30),"Above Average Size","") -> Above Average Size | S22: =IF(F22="Active",ROUND(K22/E22,2),"") -> 25.91 | T22: =_xlfn.IFS(AND(F22="Active",K22>=_xlfn.PERCENTILE.INC($K$2:$K$24,75%)),"Premium Account",F22="Vacant","",AND(F22="Active",K22<_xlfn.PERCENTILE.INC($K$2:$K$24,75%)),"Standard") -> Premium Account | U22: =IF(F22="Active",YEAR(I22),"") -> 2022
A23: T022 | B23: Crown Point Plaza | C23: Delhi | D23: Office | E23: 58000 | F23: Active | G23: Summit Legal Partners | H23: Professional Services | I23: 2020-09-01 | J23: 2026-08-31 | K23: 2530000 | L23: Anand Verma | M23: =IF(F23<>"Active","",K23/'FX Rate Table'!$B$2) -> 30299.401 | N23: =IF(F23<>"Active","",K23*12) -> 30360000 | O23: =IF(F23<>"Active","",M23*12) -> 363592.81 | P23: =IF(F23="Active",DATEDIF(I23,J23,"y"),"") -> 5 | Q23: =IF(F23="Active",_xlfn.IFS(P23<3,"Short-Term",P23>=3,"Long-Term"),"") -> Long-Term | R23: =IF(AND(F23="Active",E23>$B$30),"Above Average Size","") | S23: =IF(F23="Active",ROUND(K23/E23,2),"") -> 43.62 | T23: =_xlfn.IFS(AND(F23="Active",K23>=_xlfn.PERCENTILE.INC($K$2:$K$24,75%)),"Premium Account",F23="Vacant","",AND(F23="Active",K23<_xlfn.PERCENTILE.INC($K$2:$K$24,75%)),"Standard") -> Standard | U23: =IF(F23="Active",YEAR(I23),"") -> 2020
A24: T023 | B24: Crown Point Plaza | C24: Delhi | D24: Office | E24: 58000 | F24: Active | G24: Summit Legal Partners | H24: Professional Services | I24: 2020-09-01 | J24: 2026-08-31 | K24: 2530000 | L24: Anand Verma | M24: =IF(F24<>"Active","",K24/'FX Rate Table'!$B$2) -> 30299.401 | N24: =IF(F24<>"Active","",K24*12) -> 30360000 | O24: =IF(F24<>"Active","",M24*12) -> 363592.81 | P24: =IF(F24="Active",DATEDIF(I24,J24,"y"),"") -> 5 | Q24: =IF(F24="Active",_xlfn.IFS(P24<3,"Short-Term",P24>=3,"Long-Term"),"") -> Long-Term | R24: =IF(AND(F24="Active",E24>$B$30),"Above Average Size","") | S24: =IF(F24="Active",ROUND(K24/E24,2),"") -> 43.62 | T24: =_xlfn.IFS(AND(F24="Active",K24>=_xlfn.PERCENTILE.INC($K$2:$K$24,75%)),"Premium Account",F24="Vacant","",AND(F24="Active",K24<_xlfn.PERCENTILE.INC($K$2:$K$24,75%)),"Standard") -> Standard | U24: =IF(F24="Active",YEAR(I24),"") -> 2020
Q25: =IF(G25="Active",DATEDIF(J25,K25,"y"),"") | R25: =IF(AND(F25="Active",E25>$B$30),"Above Average Size","") | U25: =IF(F25="Active",YEAR(I25),"")
Q26: =IF(G26="Active",DATEDIF(J26,K26,"y"),"") | R26: =IF(AND(F26="Active",E26>$B$30),"Above Average Size","") | U26: =IF(F26="Active",YEAR(I26),"")
A27: Count how many unique properties exist in the portfolio (duplicate lease rows should count as one property). | Q27: =IF(G27="Active",DATEDIF(J27,K27,"y"),"") | R27: =IF(AND(F27="Active",E27>$B$30),"Above Average Size","") | U27: =IF(F27="Active",YEAR(I27),"")
A28: =SUMPRODUCT((B2:B24<>"")/COUNTIF(B2:B24,B2:B24&"")) -> 13 | Q28: =IF(G28="Active",DATEDIF(J28,K28,"y"),"") | R28: =IF(AND(F28="Active",E28>$B$30),"Above Average Size","") | U28: =IF(F28="Active",YEAR(I28),"")
Q29: =IF(G29="Active",DATEDIF(J29,K29,"y"),"") | R29: =IF(AND(F29="Active",E29>$B$30),"Above Average Size","") | U29: =IF(F29="Active",YEAR(I29),"")
A30: Avg Total Area | B30: =ROUND(AVERAGEIF(F2:F24,"Active",E2:E24),2) -> 68476.19 | Q30: =IF(G30="Active",DATEDIF(J30,K30,"y"),"") | R30: =IF(AND(F30="Active",E30>$B$30),"Above Average Size","") | U30: =IF(F30="Active",YEAR(I30),"")
Q31: =IF(G31="Active",DATEDIF(J31,K31,"y"),"") | R31: =IF(AND(F31="Active",E31>$B$30),"Above Average Size","") | U31: =IF(F31="Active",YEAR(I31),"")
A32: Tenant Industry generates the highest total active Monthly Rent | Q32: =IF(G32="Active",DATEDIF(J32,K32,"y"),"") | R32: =IF(AND(F32="Active",E32>$B$30),"Above Average Size","") | U32: =IF(F32="Active",YEAR(I32),"")
A33: Tenant Industry | B33: montly rent | Q33: =IF(G33="Active",DATEDIF(J33,K33,"y"),"") | R33: =IF(AND(F33="Active",E33>$B$30),"Above Average Size","") | U33: =IF(F33="Active",YEAR(I33),"")
A34: It Services | B34: =SUMIFS($K$2:$K$24,$F$2:$F$24,"Active",$H$2:$H$24,A34) -> 8040000 | R34: =IF(AND(F34="Active",E34>$B$30),"Above Average Size","") | U34: =IF(F34="Active",YEAR(I34),"")
A35: Finance | B35: =SUMIFS($K$2:$K$24,$F$2:$F$24,"Active",$H$2:$H$24,A35) -> 11620000 | R35: =IF(AND(F35="Active",E35>$B$30),"Above Average Size","") | U35: =IF(F35="Active",YEAR(I35),"")
A36: Retail Trade | B36: =SUMIFS($K$2:$K$24,$F$2:$F$24,"Active",$H$2:$H$24,A36) -> 1780000 | R36: =IF(AND(F36="Active",E36>$B$30),"Above Average Size","") | U36: =IF(F36="Active",YEAR(I36),"")
A37: Logistics | B37: =SUMIFS($K$2:$K$24,$F$2:$F$24,"Active",$H$2:$H$24,A37) -> 17800000 | R37: =IF(AND(F37="Active",E37>$B$30),"Above Average Size","") | U37: =IF(F37="Active",YEAR(I37),"")
A38: Fashion Retail | B38: =SUMIFS($K$2:$K$24,$F$2:$F$24,"Active",$H$2:$H$24,A38) -> 1410000 | R38: =IF(AND(F38="Active",E38>$B$30),"Above Average Size","") | U38: =IF(F38="Active",YEAR(I38),"")
A39: Food & Beverage | B39: =SUMIFS($K$2:$K$24,$F$2:$F$24,"Active",$H$2:$H$24,A39) -> 1520000 | R39: =IF(AND(F39="Active",E39>$B$30),"Above Average Size","") | U39: =IF(F39="Active",YEAR(I39),"")
A40: Professional Services | B40: =SUMIFS($K$2:$K$24,$F$2:$F$24,"Active",$H$2:$H$24,A40) -> 6780000 | R40: =IF(AND(F40="Active",E40>$B$30),"Above Average Size","") | U40: =IF(F40="Active",YEAR(I40),"")
...

Sheet FX Rate Table
A1: Currency | B1: Rate (INR per unit)
A2: USD | B2: 83.5
A3: EUR | B3: 90.2
A4: GBP | B4: 105.3

Sheet Pivot Table
A1: Build a Pivot Table: City (rows) x Property Type (columns) x Sum of Annual Rent (USD) (values).
A3: Sum of Annual Rent (USD) | B3: Property Type
A4: City | B4: Industrial | C4: Office | D4: Retail | E4: Grand Total
A5: Bengaluru | C5: 569101.8 | D5: 202634.73 | E5: 771736.53
A6: Chennai | D6: 474251.5 | E6: 474251.5
A7: Delhi | B7: 922634.73 | C7: 727185.63 | E7: 1649820.4
A8: Hyderabad | C8: 1669940.1 | E8: 1669940.1
A9: Mumbai | B9: 1635449.1 | E9: 1635449.1
A10: Pune | C10: 833532.93 | E10: 833532.93
A11: Grand Total | B11: 2558083.8 | C11: 3799760.5 | D11: 676886.23 | E11: 7034730.5

Sheet Practice Tasks
A1: Timed Practice Drill - Assignment 3
A3: # | B3: Task | C3: Suggested time
A4: 1 | B4: Count how many unique properties exist in the portfolio (duplicate lease rows should count as one property). | C4: 2 min | D4: done
A5: 2 | B5: Clean Tenant Industry into consistent Title Case in a new column. | C5: 2 min | D5: done
A6: 3 | B6: Convert each active lease's Monthly Rent from INR to USD, using the FX Rate Table (don't hardcode the rate). | C6: 3 min | D6: done
A7: 4 | B7: Calculate each active lease's Annual Rent in both INR and USD. | C7: 2 min | D7: done
A8: 5 | B8: Calculate each property's lease term length in years (Lease Start to Lease End). | C8: 3 min | D8: done
A9: 6 | B9: Classify each lease as 'Short-Term' (under 3 years) or 'Long-Term' (3 years or more). | C9: 2 min | D9: done
A10: 7 | B10: Calculate the portfolio's average Total Area across active leases — as a formula, not a typed-in number — then flag every property above that average as 'Above Average Size'. | C10: 4 min | D10: done
A11: 8 | B11: Find which Tenant Industry generates the highest total active Monthly Rent, and show the amount. | C11: 4 min | D11: done
A12: 9 | B12: Calculate each City's share of total active portfolio rent, as a percentage. | C12: 4 min | D12: done
A13: 10 | B13: Find the property with the lowest rent per sqft among all active leases. | C13: 4 min | D13: done
A14: 11 | B14: Find the second-highest Monthly Rent in the entire portfolio (not the highest). | C14: 3 min | D14: done
A15: 12 | B15: Classify each active lease as 'Premium Account' if its Monthly Rent is in the top 25% of all active leases, else 'Standard'. | C15: 4 min | D15: done
... A20: 17 | B20: Apply conditional formatting to highlight 'Long-Term' leases in one colour and 'Short-Term' in another. | C20: 3 min | D20: done
A22: Suggested total time: ~58 minutes

Sheet Answer Key
A1: Property ID | B1: Property Name | C1: City | D1: Property Type | E1: Status | F1: Total Area (sqft) | G1: Monthly Rent (INR) | H1: Tenant Industry (clean) | I1: Lease Start Date | J1: Lease End Date | K1: Landlord Contact | L1: Rent (USD) | M1: Annual Rent (INR) | N1: Annual Rent (USD) | O1: Lease Term (yrs) | P1: Term Class | Q1: Above Avg Size | R1: Premium Account | S1: Cleanup Flag | T1: Lease Start Year | U1: Active Rent (helper) | W1: Active Rent/Sqft (helper) | X1: Property Name (trimmed, helper)
A2: ='Portfolio Data (Modified)'!A2 -> T001 | B2: ='Portfolio Data (Modified)'!B2 -> Horizon Corporate Suites | C2: =PROPER(TRIM('Portfolio Data (Modified)'!#REF!)) -> #REF! | D2: =PROPER(TRIM('Portfolio Data (Modified)'!#REF!)) -> #REF! | E2: =PROPER(TRIM('Portfolio Data (Modified)'!#REF!)) -> #REF! | F2: ='Portfolio Data (Modified)'!E2 -> 49000 | G2: ='Portfolio Data (Modified)'!K2 -> 1980000 | H2: =IF('Portfolio Data (Modified)'!#REF!="","",PROPER('Portfolio Data (Modified)'!#REF!)) -> #REF! | I2: ='Portfolio Data (Modified)'!I2 -> 2021-06-01 | J2: ='Portfolio Data (Modified)'!J2 -> 2027-05-31 | K2: =IF('Portfolio Data (Modified)'!L2="","",'Portfolio Data (Modified)'!L2) -> Rajan Mehta | L2: =IF(E2<>"Active","",ROUND(G2/VLOOKUP("USD",'FX Rate Table'!$A$2:$B$4,2,FALSE()),2)) -> #REF! | M2: =IF(E2<>"Active","",G2*12) -> #REF! | N2: =IF(E2<>"Active","",L2*12) -> #REF! | O2: =IF(E2<>"Active","",ROUND((DATEVALUE(J2)-DATEVALUE(I2))/365.25,1)) -> #REF! | P2: =IF(E2<>"Active","",IF(O2>=3,"Long-Term","Short-Term")) -> #REF! | Q2: =IF(E2<>"Active","",IF(F2>AVERAGEIF($E$2:$E$24,"Active",$F$2:$F$24),"Above Average Size","")) -> #REF! | R2: =IF(E2<>"Active","",IF(G2>=PERCENTILE($U$2:$U$24,0.75),"Premium Account","Standard")) -> #REF! | S2: =IF(OR('Portfolio Data (Modified)'!B2<>TRIM('Portfolio Data (Modified)'!B2),'Portfolio Data (Modified)'!#REF!<>PROPER(TRIM('Portfolio Data (Modified)'!#REF!))),"Needs Cleanup","") -> #REF! | T2: =IF(E2<>"Active","",YEAR(DATEVALUE(I2))) -> #REF! | U2: =IF(E2<>"Active","",G2) -> #REF! | W2: =IF(E2<>"Active","",ROUND(G2/F2,2)) -> #REF! | X2: =TRIM(B2) -> Horizon Corporate Suites
A3: ='Portfolio Data (Modified)'!A3 -> T002 | B3: ='Portfolio Data (Modified)'!B3 -> Horizon Corporate Suites | C3: =PROPER(TRIM('Portfolio Data (Modified)'!#REF!)) -> #REF! | D3: =PROPER(TRIM('Portfolio Data (Modified)'!#REF!)) -> #REF! | E3: =PROPER(TRIM('Portfolio Data (Modified)'!#REF!)) -> #REF! | F3: ='Portfolio Data (Modified)'!E3 -> 49000 | G3: ='Portfolio Data (Modified)'!K3 -> 1980000 | H3: =IF('Portfolio Data (Modified)'!#REF!="","",PROPER('Portfolio Data (Modified)'!#REF!)) -> #REF! | I3: ='Portfolio Data (Modified)'!I3 -> 2021-06-01 | J3: ='Portfolio Data (Modified)'!J3 -> 2027-05-31 | K3: =IF('Portfolio Data (Modified)'!L3="","",'Portfolio Data (Modified)'!L3) -> Rajan Mehta | L3: =IF(E3<>"Active","",ROUND(G3/VLOOKUP("USD",'FX Rate Table'!$A$2:$B$4,2,FALSE()),2)) -> #REF! | M3: =IF(E3<>"Active","",G3*12) -> #REF! | N3: =IF(E3<>"Active","",L3*12) -> #REF! | O3: =IF(E3<>"Active","",ROUND((DATEVALUE(J3)-DATEVALUE(I3))/365.25,1)) -> #REF! | P3: =IF(E3<>"Active","",IF(O3>=3,"Long-Term","Short-Term")) -> #REF! | Q3: =IF(E3<>"Active","",IF(F3>AVERAGEIF($E$2:$E$24,"Active",$F$2:$F$24),"Above Average Size","")) -> #REF! | R3: =IF(E3<>"Active","",IF(G3>=PERCENTILE($U$2:$U$24,0.75),"Premium Account","Standard")) -> #REF! | S3: =IF(OR('Portfolio Data (Modified)'!B3<>TRIM('Portfolio Data (Modified)'!B3),'Portfolio Data (Modified)'!#REF!<>PROPER(TRIM('Portfolio Data (Modified)'!#REF!))),"Needs Cleanup","") -> #REF! | T3: =IF(E3<>"Active","",YEAR(DATEVALUE(I3))) -> #REF! | U3: =IF(E3<>"Active","",G3) -> #REF! | W3: =IF(E3<>"Active","",ROUND(G3/F3,2)) -> #REF! | X3: =TRIM(B3) -> Horizon Corporate Suites
A4: ='Portfolio Data (Modified)'!A4 -> T003 | B4: ='Portfolio Data (Modified)'!B4 -> Meridian Trade Tower | C4: =PROPER(TRIM('Portfolio Data (Modified)'!#REF!)) -> #REF! | D4: =PROPER(TRIM('Portfolio Data (Modified)'!#REF!)) -> #REF! | E4: =PROPER(TRIM('Portfolio Data (Modified)'!#REF!)) -> #REF! | F4: ='Portfolio Data (Modified)'!E4 -> 73000 | G4: ='Portfolio Data (Modified)'!K4 -> 3050000 | H4: =IF('Portfolio Data (Modified)'!#REF!="","",PROPER('Portfolio Data (Modified)'!#REF!)) -> #REF! | I4: ='Portfolio Data (Modified)'!I4 -> 2020-02-10 | J4: ='Portfolio Data (Modified)'!J4 -> 2028-02-09 | K4: =IF('Portfolio Data (Modified)'!L4="","",'Portfolio Data (Modified)'!L4) -> Kavya Rao | L4: =IF(E4<>"Active","",ROUND(G4/VLOOKUP("USD",'FX Rate Table'!$A$2:$B$4,2,FALSE()),2)) -> #REF! | M4: =IF(E4<>"Active","",G4*12) -> #REF! | N4: =IF(E4<>"Active","",L4*12) -> #REF! | O4: =IF(E4<>"Active","",ROUND((DATEVALUE(J4)-DATEVALUE(I4))/365.25,1)) -> #REF! | P4: =IF(E4<>"Active","",IF(O4>=3,"Long-Term","Short-Term")) -> #REF! | Q4: =IF(E4<>"Active","",IF(F4>AVERAGEIF($E$2:$E$24,"Active",$F$2:$F$24),"Above Average Size","")) -> #REF! | R4: =IF(E4<>"Active","",IF(G4>=PERCENTILE($U$2:$U$24,0.75),"Premium Account","Standard")) -> #REF! | S4: =IF(OR('Portfolio Data (Modified)'!B4<>TRIM('Portfolio Data (Modified)'!B4),'Portfolio Data (Modified)'!#REF!<>PROPER(TRIM('Portfolio Data (Modified)'!#REF!))),"Needs Cleanup","") -> #REF! | T4: =IF(E4<>"Active","",YEAR(DATEVALUE(I4))) -> #REF! | U4: =IF(E4<>"Active","",G4) -> #REF! | W4: =IF(E4<>"Active","",ROUND(G4/F4,2)) -> #REF! | X4: =TRIM(B4) -> Meridian Trade Tower
A5: ='Portfolio Data (Modified)'!A5 -> T004 | B5: ='Portfolio Data (Modified)'!B5 -> Meridian Trade Tower | C5: =PROPER(TRIM('Portfolio Data (Modified)'!#REF!)) -> #REF! | D5: =PROPER(TRIM('Portfolio Data (Modified)'!#REF!)) -> #REF! | E5: =PROPER(TRIM('Portfolio Data (Modified)'!#REF!)) -> #REF! | F5: ='Portfolio Data (Modified)'!E5 -> 73000 | G5: ='Portfolio Data (Modified)'!K5 -> 3050000 | H5: =IF('Portfolio Data (Modified)'!#REF!="","",PROPER('Portfolio Data (Modified)'!#REF!)) -> #REF! | I5: ='Portfolio Data (Modified)'!I5 -> 2020-02-10 | J5: ='Portfolio Data (Modified)'!J5 -> 2028-02-09 | K5: =IF('Portfolio Data (Modified)'!L5="","",'Portfolio Data (Modified)'!L5) -> Kavya Rao | L5: =IF(E5<>"Active","",ROUND(G5/VLOOKUP("USD",'FX Rate Table'!$A$2:$B$4,2,FALSE()),2)) -> #REF! | M5: =IF(E5<>"Active","",G5*12) -> #REF! | N5: =IF(E5<>"Active","",L5*12) -> #REF! | O5: =IF(E5<>"Active","",ROUND((DATEVALUE(J5)-DATEVALUE(I5))/365.25,1)) -> #REF! | P5: =IF(E5<>"Active","",IF(O5>=3,"Long-Term","Short-Term")) -> #REF! | Q5: =IF(E5<>"Active","",IF(F5>AVERAGEIF($E$2:$E$24,"Active",$F$2:$F$24),"Above Average Size","")) -> #REF! | R5: =IF(E5<>"Active","",IF(G5>=PERCENTILE($U$2:$U$24,0.75),"Premium Account","Standard")) -> #REF! | S5: =IF(OR('Portfolio Data (Modified)'!B5<>TRIM('Portfolio Data (Modified)'!B5),'Portfolio Data (Modified)'!#REF!<>PROPER(TRIM('Portfolio Data (Modified)'!#REF!))),"Needs Cleanup","") -> #REF! | T5: =IF(E5<>"Active","",YEAR(DATEVALUE(I5))) -> #REF! | U5: =IF(E5<>"Active","",G5) -> #REF! | W5: =IF(E5<>"Active","",ROUND(G5/F5,2)) -> #REF! | X5: =TRIM(B5) -> Meridian Trade Tower
A6: ='Portfolio Data (Modified)'!A6 -> T005 | B6: ='Portfolio Data (Modified)'!B6 -> Cedar Grove Outlet | C6: =PROPER(TRIM('Portfolio Data (Modified)'!#REF!)) -> #REF! | D6: =PROPER(TRIM('Portfolio Data (Modified)'!#REF!)) -> #REF! | E6: =PROPER(TRIM('Portfolio Data (Modified)'!#REF!)) -> #REF! | F6: ='Portfolio Data (Modified)'!E6 -> 21000 | G6: ='Portfolio Data (Modified)'!K6 -> 890000 | H6: =IF('Portfolio Data (Modified)'!#REF!="","",PROPER('Portfolio Data (Modified)'!#REF!)) -> #REF! | I6: ='Portfolio Data (Modified)'!I6 -> 2023-09-01 | J6: ='Portfolio Data (Modified)'!J6 -> 2025-08-31 | K6: =IF('Portfolio Data (Modified)'!L6="","",'Portfolio Data (Modified)'!L6) | L6: =IF(E6<>"Active","",ROUND(G6/VLOOKUP("USD",'FX Rate Table'!$A$2:$B$4,2,FALSE()),2)) -> #REF! | M6: =IF(E6<>"Active","",G6*12) -> #REF! | N6: =IF(E6<>"Active","",L6*12) -> #REF! | O6: =IF(E6<>"Active","",ROUND((DATEVALUE(J6)-DATEVALUE(I6))/365.25,1)) -> #REF! | P6: =IF(E6<>"Active","",IF(O6>=3,"Long-Term","Short-Term")) -> #REF! | Q6: =IF(E6<>"Active","",IF(F6>AVERAGEIF($E$2:$E$24,"Active",$F$2:$F$24),"Above Average Size","")) -> #REF! | R6: =IF(E6<>"Active","",IF(G6>=PERCENTILE($U$2:$U$24,0.75),"Premium Account","Standard")) -> #REF! | S6: =IF(OR('Portfolio Data (Modified)'!B6<>TRIM('Portfolio Data (Modified)'!B6),'Portfolio Data (Modified)'!#REF!<>PROPER(TRIM('Portfolio Data (Modified)'!#REF!))),"Needs Cleanup","") -> #REF! | T6: =IF(E6<>"Active","",YEAR(DATEVALUE(I6))) -> #REF! | U6: =IF(E6<>"Active","",G6) -> #REF! | W6: =IF(E6<>"Active","",ROUND(G6/F6,2)) -> #REF! | X6: =TRIM(B6) -> Cedar Grove Outlet
A7: ='Portfolio Data (Modified)'!A7 -> T006 | B7: ='Portfolio Data (Modified)'!B7 -> Cedar Grove Outlet | C7: =PROPER(TRIM('Portfolio Data (Modified)'!#REF!)) -> #REF! | D7: =PROPER(TRIM('Portfolio Data (Modified)'!#REF!)) -> #REF! | E7: =PROPER(TRIM('Portfolio Data (Modified)'!#REF!)) -> #REF! | F7: ='Portfolio Data (Modified)'!E7 -> 21000 | G7: ='Portfolio Data (Modified)'!K7 -> 890000 | H7: =IF('Portfolio Data (Modified)'!#REF!="","",PROPER('Portfolio Data (Modified)'!#REF!)) -> #REF! | I7: ='Portfolio Data (Modified)'!I7 -> 2023-09-01 | J7: ='Portfolio Data (Modified)'!J7 -> 2025-08-31 | K7: =IF('Portfolio Data (Modified)'!L7="","",'Portfolio Data (Modified)'!L7) | L7: =IF(E7<>"Active","",ROUND(G7/VLOOKUP("USD",'FX Rate Table'!$A$2:$B$4,2,FALSE()),2)) -> #REF! | M7: =IF(E7<>"Active","",G7*12) -> #REF! | N7: =IF(E7<>"Active","",L7*12) -> #REF! | O7: =IF(E7<>"Active","",ROUND((DATEVALUE(J7)-DATEVALUE(I7))/365.25,1)) -> #REF! | P7: =IF(E7<>"Active","",IF(O7>=3,"Long-Term","Short-Term")) -> #REF! | Q7: =IF(E7<>"Active","",IF(F7>AVERAGEIF($E$2:$E$24,"Active",$F$2:$F$24),"Above Average Size","")) -> #REF! | R7: =IF(E7<>"Active","",IF(G7>=PERCENTILE($U$2:$U$24,0.75),"Premium Account","Standard")) -> #REF! | S7: =IF(OR('Portfolio Data (Modified)'!B7<>TRIM('Portfolio Data (Modified)'!B7),'Portfolio Data (Modified)'!#REF!<>PROPER(TRIM('Portfolio Data (Modified)'!#REF!))),"Needs Cleanup","") -> #REF! | T7: =IF(E7<>"Active","",YEAR(DATEVALUE(I7))) -> #REF! | U7: =IF(E7<>"Active","",G7) -> #REF! | W7: =IF(E7<>"Active","",ROUND(G7/F7,2)) -> #REF! | X7: =TRIM(B7) -> Cedar Grove Outlet
A8: ='Portfolio Data (Modified)'!A8 -> T007 | B8: ='Portfolio Data (Modified)'!B8 -> Portside Storage Hub | C8: =PROPER(TRIM('Portfolio Data (Modified)'!#REF!)) -> #REF! | D8: =PROPER(TRIM('Portfolio Data (Modified)'!#REF!)) -> #REF! | E8: =PROPER(TRIM('Portfolio Data (Modified)'!#REF!)) -> #REF! | F8: ='Portfolio Data (Modified)'!E8 -> 158000 | G8: ='Portfolio Data (Modified)'!K8 -> 3980000 | H8: =IF('Portfolio Data (Modified)'!#REF!="","",PROPER('Portfolio Data (Modified)'!#REF!)) -> #REF! | I8: ='Portfolio Data (Modified)'!I8 -> 2019-04-15 | J8: ='Portfolio Data (Modified)'!J8 -> 2029-04-14 | K8: =IF('Portfolio Data (Modified)'!L8="","",'Portfolio Data (Modified)'!L8) -> Imran Sheikh | L8: =IF(E8<>"Active","",ROUND(G8/VLOOKUP("USD",'FX Rate Table'!$A$2:$B$4,2,FALSE()),2)) -> #REF! | M8: =IF(E8<>"Active","",G8*12) -> #REF! | N8: =IF(E8<>"Active","",L8*12) -> #REF! | O8: =IF(E8<>"Active","",ROUND((DATEVALUE(J8)-DATEVALUE(I8))/365.25,1)) -> #REF! | P8: =IF(E8<>"Active","",IF(O8>=3,"Long-Term","Short-Term")) -> #REF! | Q8: =IF(E8<>"Active","",IF(F8>AVERAGEIF($E$2:$E$24,"Active",$F$2:$F$24),"Above Average Size","")) -> #REF! | R8: =IF(E8<>"Active","",IF(G8>=PERCENTILE($U$2:$U$24,0.75),"Premium Account","Standard")) -> #REF! | S8: =IF(OR('Portfolio Data (Modified)'!B8<>TRIM('Portfolio Data (Modified)'!B8),'Portfolio Data (Modified)'!#REF!<>PROPER(TRIM('Portfolio Data (Modified)'!#REF!))),"Needs Cleanup","") -> #REF! | T8: =IF(E8<>"Active","",YEAR(DATEVALUE(I8))) -> #REF! | U8: =IF(E8<>"Active","",G8) -> #REF! | W8: =IF(E8<>"Active","",ROUND(G8/F8,2)) -> #REF! | X8: =TRIM(B8) -> Portside Storage Hub
A9: ='Portfolio Data (Modified)'!A9 -> T008 | B9: ='Portfolio Data (Modified)'!B9 -> Portside Storage Hub | C9: =PROPER(TRIM('Portfolio Data (Modified)'!#REF!)) -> #REF! | D9: =PROPER(TRIM('Portfolio Data (Modified)'!#REF!)) -> #REF! | E9: =PROPER(TRIM('Portfolio Data (Modified)'!#REF!)) -> #REF! | F9: ='Portfolio Data (Modified)'!E9 -> 158000 | G9: ='Portfolio Data (Modified)'!K9 -> 3980000 | H9: =IF('Portfolio Data (Modified)'!#REF!="","",PROPER('Portfolio Data (Modified)'!#REF!)) -> #REF! | I9: ='Portfolio Data (Modified)'!I9 -> 2019-04-15 | J9: ='Portfolio Data (Modified)'!J9 -> 2029-04-14 | K9: =IF('Portfolio Data (Modified)'!L9="","",'Portfolio Data (Modified)'!L9) -> Imran Sheikh | L9: =IF(E9<>"Active","",ROUND(G9/VLOOKUP("USD",'FX Rate Table'!$A$2:$B$4,2,FALSE()),2)) -> #REF! | M9: =IF(E9<>"Active","",G9*12) -> #REF! | N9: =IF(E9<>"Active","",L9*12) -> #REF! | O9: =IF(E9<>"Active","",ROUND((DATEVALUE(J9)-DATEVALUE(I9))/365.25,1)) -> #REF! | P9: =IF(E9<>"Active","",IF(O9>=3,"Long-Term","Short-Term")) -> #REF! | Q9: =IF(E9<>"Active","",IF(F9>AVERAGEIF($E$2:$E$24,"Active",$F$2:$F$24),"Above Average Size","")) -> #REF! | R9: =IF(E9<>"Active","",IF(G9>=PERCENTILE($U$2:$U$24,0.75),"Premium Account","Standard")) -> #REF! | S9: =IF(OR('Portfolio Data (Modified)'!B9<>TRIM('Portfolio Data (Modified)'!B9),'Portfolio Data (Modified)'!#REF!<>PROPER(TRIM('Portfolio Data (Modified)'!#REF!))),"Needs Cleanup","") -> #REF! | T9: =IF(E9<>"Active","",YEAR(DATEVALUE(I9))) -> #REF! | U9: =IF(E9<>"Active","",G9) -> #REF! | W9: =IF(E9<>"Active","",ROUND(G9/F9,2)) -> #REF! | X9: =TRIM(B9) -> Portside Storage Hub
A10: ='Portfolio Data (Modified)'!A10 -> T009 | B10: ='Portfolio Data (Modified)'!B10 -> Willowbrook IT Park | C10: =PROPER(TRIM('Portfolio Data (Modified)'!#REF!)) -> #REF! | D10: =PROPER(TRIM('Portfolio Data (Modified)'!#REF!)) -> #REF! | E10: =PROPER(TRIM('Portfolio Data (Modified)'!#REF!)) -> #REF! | F10: ='Portfolio Data (Modified)'!E10 -> 51000 | G10: ='Portfolio Data (Modified)'!K10 -> 2040000 | H10: =IF('Portfolio Data (Modified)'!#REF!="","",PROPER('Portfolio Data (Modified)'!#REF!)) -> #REF! | I10: ='Portfolio Data (Modified)'!I10 -> 2022-11-01 | J10: ='Portfolio Data (Modified)'!J10 -> 2025-10-31 | K10: =IF('Portfolio Data (Modified)'!L10="","",'Portfolio Data (Modified)'!L10) -> Sneha Kulkarni | L10: =IF(E10<>"Active","",ROUND(G10/VLOOKUP("USD",'FX Rate Table'!$A$2:$B$4,2,FALSE()),2)) -> #REF! | M10: =IF(E10<>"Active","",G10*12) -> #REF! | N10: =IF(E10<>"Active","",L10*12) -> #REF! | O10: =IF(E10<>"Active","",ROUND((DATEVALUE(J10)-DATEVALUE(I10))/365.25,1)) -> #REF! | P10: =IF(E10<>"Active","",IF(O10>=3,"Long-Term","Short-Term")) -> #REF! | Q10: =IF(E10<>"Active","",IF(F10>AVERAGEIF($E$2:$E$24,"Active",$F$2:$F$24),"Above Average Size","")) -> #REF! | R10: =IF(E10<>"Active","",IF(G10>=PERCENTILE($U$2:$U$24,0.75),"Premium Account","Standard")) -> #REF! | S10: =IF(OR('Portfolio Data (Modified)'!B10<>TRIM('Portfolio Data (Modified)'!B10),'Portfolio Data (Modified)'!#REF!<>PROPER(TRIM('Portfolio Data (Modified)'!#REF!))),"Needs Cleanup","") -> #REF! | T10: =IF(E10<>"Active","",YEAR(DATEVALUE(I10))) -> #REF! | U10: =IF(E10<>"Active","",G10) -> #REF! | W10: =IF(E10<>"Active","",ROUND(G10/F10,2)) -> #REF! | X10: =TRIM(B10) -> Willowbrook IT Park
A11: ='Portfolio Data (Modified)'!A11 -> T010 | B11: ='Portfolio Data (Modified)'!B11 -> Willowbrook IT Park | C11: =PROPER(TRIM('Portfolio Data (Modified)'!#REF!)) -> #REF! | D11: =PROPER(TRIM('Portfolio Data (Modified)'!#REF!)) -> #REF! | E11: =PROPER(TRIM('Portfolio Data (Modified)'!#REF!)) -> #REF! | F11: ='Portfolio Data (Modified)'!E11 -> 51000 | G11: ='Portfolio Data (Modified)'!K11 -> 2040000 | H11: =IF('Portfolio Data (Modified)'!#REF!="","",PROPER('Portfolio Data (Modified)'!#REF!)) -> #REF! | I11: ='Portfolio Data (Modified)'!I11 -> 2022-11-01 | J11: ='Portfolio Data (Modified)'!J11 -> 2025-10-31 | K11: =IF('Portfolio Data (Modified)'!L11="","",'Portfolio Data (Modified)'!L11) -> Sneha Kulkarni | L11: =IF(E11<>"Active","",ROUND(G11/VLOOKUP("USD",'FX Rate Table'!$A$2:$B$4,2,FALSE()),2)) -> #REF! | M11: =IF(E11<>"Active","",G11*12) -> #REF! | N11: =IF(E11<>"Active","",L11*12) -> #REF! | O11: =IF(E11<>"Active","",ROUND((DATEVALUE(J11)-DATEVALUE(I11))/365.25,1)) -> #REF! | P11: =IF(E11<>"Active","",IF(O11>=3,"Long-Term","Short-Term")) -> #REF! | Q11: =IF(E11<>"Active","",IF(F11>AVERAGEIF($E$2:$E$24,"Active",$F$2:$F$24),"Above Average Size","")) -> #REF! | R11: =IF(E11<>"Active","",IF(G11>=PERCENTILE($U$2:$U$24,0.75),"Premium Account","Standard")) -> #REF! | S11: =IF(OR('Portfolio Data (Modified)'!B11<>TRIM('Portfolio Data (Modified)'!B11),'Portfolio Data (Modified)'!#REF!<>PROPER(TRIM('Portfolio Data (Modified)'!#REF!))),"Needs Cleanup","") -> #REF! | T11: =IF(E11<>"Active","",YEAR(DATEVALUE(I11))) -> #REF! | U11: =IF(E11<>"Active","",G11) -> #REF! | W11: =IF(E11<>"Active","",ROUND(G11/F11,2)) -> #REF! | X11: =TRIM(B11) -> Willowbrook IT Park
A12: ='Portfolio Data (Modified)'!A12 -> T011 | B12: ='Portfolio Data (Modified)'!B12 -> Clover Street Mall | C12: =PROPER(TRIM('Portfolio Data (Modified)'!#REF!)) -> #REF! | D12: =PROPER(TRIM('Portfolio Data (Modified)'!#REF!)) -> #REF! | E12: =PROPER(TRIM('Portfolio Data (Modified)'!#REF!)) -> #REF! | F12: ='Portfolio Data (Modified)'!E12 -> 33000 | G12: ='Portfolio Data (Modified)'!K12 -> 1410000 | H12: =IF('Portfolio Data (Modified)'!#REF!="","",PROPER('Portfolio Data (Modified)'!#REF!)) -> #REF! | I12: ='Portfolio Data (Modified)'!I12 -> 2024-02-01 | J12: ='Portfolio Data (Modified)'!J12 -> 2026-01-31 | K12: =IF('Portfolio Data (Modified)'!L12="","",'Portfolio Data (Modified)'!L12) -> Farhan Ali | L12: =IF(E12<>"Active","",ROUND(G12/VLOOKUP("USD",'FX Rate Table'!$A$2:$B$4,2,FALSE()),2)) -> #REF! | M12: =IF(E12<>"Active","",G12*12) -> #REF! | N12: =IF(E12<>"Active","",L12*12) -> #REF! | O12: =IF(E12<>"Active","",ROUND((DATEVALUE(J12)-DATEVALUE(I12))/365.25,1)) -> #REF! | P12: =IF(E12<>"Active","",IF(O12>=3,"Long-Term","Short-Term")) -> #REF! | Q12: =IF(E12<>"Active","",IF(F12>AVERAGEIF($E$2:$E$24,"Active",$F$2:$F$24),"Above Average Size","")) -> #REF! | R12: =IF(E12<>"Active","",IF(G12>=PERCENTILE($U$2:$U$24,0.75),"Premium Account","Standard")) -> #REF! | S12: =IF(OR('Portfolio Data (Modified)'!B12<>TRIM('Portfolio Data (Modified)'!B12),'Portfolio Data (Modified)'!#REF!<>PROPER(TRIM('Portfolio Data (Modified)'!#REF!))),"Needs Cleanup","") -> #REF! | T12: =IF(E12<>"Active","",YEAR(DATEVALUE(I12))) -> #REF! | U12: =IF(E12<>"Active","",G12) -> #REF! | W12: =IF(E12<>"Active","",ROUND(G12/F12,2)) -> #REF! | X12: =TRIM(B12) -> Clover Street Mall
A13: ='Portfolio Data (Modified)'!A13 -> T012 | B13: ='Portfolio Data (Modified)'!B13 -> Clover Street Mall | C13: =PROPER(TRIM('Portfolio Data (Modified)'!#REF!)) -> #REF! | D13: =PROPER(TRIM('Portfolio Data (Modified)'!#REF!)) -> #REF! | E13: =PROPER(TRIM('Portfolio Data (Modified)'!#REF!)) -> #REF! | F13: ='Portfolio Data (Modified)'!E13 -> 33000 | G13: ='Portfolio Data (Modified)'!K13 -> 0 | H13: =IF('Portfolio Data (Modified)'!#REF!="","",PROPER('Portfolio Data (Modified)'!#REF!)) -> #REF! | I13: ='Portfolio Data (Modified)'!I13 -> 0 | J13: ='Portfolio Data (Modified)'!J13 -> 0 | K13: =IF('Portfolio Data (Modified)'!L13="","",'Portfolio Data (Modified)'!L13) -> Farhan Ali | L13: =IF(E13<>"Active","",ROUND(G13/VLOOKUP("USD",'FX Rate Table'!$A$2:$B$4,2,FALSE()),2)) -> #REF! | M13: =IF(E13<>"Active","",G13*12) -> #REF! | N13: =IF(E13<>"Active","",L13*12) -> #REF! | O13: =IF(E13<>"Active","",ROUND((DATEVALUE(J13)-DATEVALUE(I13))/365.25,1)) -> #REF! | P13: =IF(E13<>"Active","",IF(O13>=3,"Long-Term","Short-Term")) -> #REF! | Q13: =IF(E13<>"Active","",IF(F13>AVERAGEIF($E$2:$E$24,"Active",$F$2:$F$24),"Above Average Size","")) -> #REF! | R13: =IF(E13<>"Active","",IF(G13>=PERCENTILE($U$2:$U$24,0.75),"Premium Account","Standard")) -> #REF! | S13: =IF(OR('Portfolio Data (Modified)'!B13<>TRIM('Portfolio Data (Modified)'!B13),'Portfolio Data (Modified)'!#REF!<>PROPER(TRIM('Portfolio Data (Modified)'!#REF!))),"Needs Cleanup","") -> #REF! | T13: =IF(E13<>"Active","",YEAR(DATEVALUE(I13))) -> #REF! | U13: =IF(E13<>"Active","",G13) -> #REF! | W13: =IF(E13<>"Active","",ROUND(G13/F13,2)) -> #REF! | X13: =TRIM(B13) -> Clover Street Mall
... A24: ='Portfolio Data (Modified)'!A24 -> T023 | B24: ='Portfolio Data (Modified)'!B24 -> Crown Point Plaza | C24: =PROPER(TRIM('Portfolio Data (Modified)'!#REF!)) -> #REF! | D24: =PROPER(TRIM('Portfolio Data (Modified)'!#REF!)) -> #REF! | E24: =PROPER(TRIM('Portfolio Data (Modified)'!#REF!)) -> #REF! | F24: ='Portfolio Data (Modified)'!E24 -> 58000 | G24: ='Portfolio Data (Modified)'!K24 -> 2530000 | H24: =IF('Portfolio Data (Modified)'!#REF!="","",PROPER('Portfolio Data (Modified)'!#REF!)) -> #REF! | I24: ='Portfolio Data (Modified)'!I24 -> 2020-09-01 | J24: ='Portfolio Data (Modified)'!J24 -> 2026-08-31 | K24: =IF('Portfolio Data (Modified)'!L24="","",'Portfolio Data (Modified)'!L24) -> Anand Verma | L24: =IF(E24<>"Active","",ROUND(G24/VLOOKUP("USD",'FX Rate Table'!$A$2:$B$4,2,FALSE()),2)) -> #REF! | M24: =IF(E24<>"Active","",G24*12) -> #REF! | N24: =IF(E24<>"Active","",L24*12) -> #REF! | O24: =IF(E24<>"Active","",ROUND((DATEVALUE(J24)-DATEVALUE(I24))/365.25,1)) -> #REF! | P24: =IF(E24<>"Active","",IF(O24>=3,"Long-Term","Short-Term")) -> #REF! | Q24: =IF(E24<>"Active","",IF(F24>AVERAGEIF($E$2:$E$24,"Active",$F$2:$F$24),"Above Average Size","")) -> #REF! | R24: =IF(E24<>"Active","",IF(G24>=PERCENTILE($U$2:$U$24,0.75),"Premium Account","Standard")) -> #REF! | S24: =IF(OR('Portfolio Data (Modified)'!B24<>TRIM('Portfolio Data (Modified)'!B24),'Portfolio Data (Modified)'!#REF!<>PROPER(TRIM('Portfolio Data (Modified)'!#REF!))),"Needs Cleanup","") -> #REF! | T24: =IF(E24<>"Active","",YEAR(DATEVALUE(I24))) -> #REF! | U24: =IF(E24<>"Active","",G24) -> #REF! | W24: =IF(E24<>"Active","",ROUND(G24/F24,2)) -> #REF! | X24: =TRIM(B24) -> Crown Point Plaza
A27: Summary answers
A28: Unique properties (Task 1) | B28: =SUMPRODUCT((X2:X24<>"")/COUNTIF(X2:X24,X2:X24&"")) -> 12
A30: Top industry by total active rent (Task 8)
A31: It Services | B31: =SUMIFS($G$2:$G$24,$H$2:$H$24,A31,$E$2:$E$24,"Active") -> 0
A32: Finance | B32: =SUMIFS($G$2:$G$24,$H$2:$H$24,A32,$E$2:$E$24,"Active") -> 0
A33: Retail Trade | B33: =SUMIFS($G$2:$G$24,$H$2:$H$24,A33,$E$2:$E$24,"Active") -> 0
A34: Logistics | B34: =SUMIFS($G$2:$G$24,$H$2:$H$24,A34,$E$2:$E$24,"Active") -> 0
A35: Fashion Retail | B35: =SUMIFS($G$2:$G$24,$H$2:$H$24,A35,$E$2:$E$24,"Active") -> 0
A36: Food & Beverage | B36: =SUMIFS($G$2:$G$24,$H$2:$H$24,A36,$E$2:$E$24,"Active") -> 0
A37: Professional Services | B37: =SUMIFS($G$2:$G$24,$H$2:$H$24,A37,$E$2:$E$24,"Active") -> 0
A38: Answer: | B38: =INDEX($A$31:$A$37,MATCH(MAX($B$31:$B$37),$B$31:$B$37,0)) -> It Services | C38: =MAX($B$31:$B$37) -> 0
A40: City share of total active rent % (Task 9)
A41: Bengaluru | B41: =ROUND(SUMIFS($G$2:$G$24,$C$2:$C$24,A41,$E$2:$E$24,"Active")/SUMIFS($G$2:$G$24,$E$2:$E$24,"Active")*100,1) -> #DIV/0!
A42: Hyderabad | B42: =ROUND(SUMIFS($G$2:$G$24,$C$2:$C$24,A42,$E$2:$E$24,"Active")/SUMIFS($G$2:$G$24,$E$2:$E$24,"Active")*100,1) -> #DIV/0!
A43: Chennai | B43: =ROUND(SUMIFS($G$2:$G$24,$C$2:$C$24,A43,$E$2:$E$24,"Active")/SUMIFS($G$2:$G$24,$E$2:$E$24,"Active")*100,1) -> #DIV/0!
A44: Mumbai | B44: =ROUND(SUMIFS($G$2:$G$24,$C$2:$C$24,A44,$E$2:$E$24,"Active")/SUMIFS($G$2:$G$24,$E$2:$E$24,"Active")*100,1) -> #DIV/0!
A45: Pune | B45: =ROUND(SUMIFS($G$2:$G$24,$C$2:$C$24,A45,$E$2:$E$24,"Active")/SUMIFS($G$2:$G$24,$E$2:$E$24,"Active")*100,1) -> #DIV/0!
A46: Delhi | B46: =ROUND(SUMIFS($G$2:$G$24,$C$2:$C$24,A46,$E$2:$E$24,"Active")/SUMIFS($G$2:$G$24,$E$2:$E$24,"Active")*100,1) -> #DIV/0!
A48: Property with lowest active rent/sqft (Task 10)
A49: Property Name: | B49: =INDEX($B$2:$B$24,MATCH(MIN($W$2:$W$24),$W$2:$W$24,0)) -> #REF!
A51: Second-highest Monthly Rent overall (Task 11) | B51: =LARGE($G$2:$G$24,2) -> 3980000
A53: Active leases missing Landlord Contact (Task 13) | B53: =COUNTIFS($E$2:$E$24,"Active",$K$2:$K$24,"") -> 0
A55: Property Type share of total active Annual Rent USD (Task 15)
A56: Office | B56: =ROUND(SUMIFS($N$2:$N$24,$D$2:$D$24,A56,$E$2:$E$24,"Active")/SUMIFS($N$2:$N$24,$E$2:$E$24,"Active")*100,1) -> #DIV/0!
A57: Retail | B57: =ROUND(SUMIFS($N$2:$N$24,$D$2:$D$24,A57,$E$2:$E$24,"Active")/SUMIFS($N$2:$N$24,$E$2:$E$24,"Active")*100,1) -> #DIV/0!
A58: Industrial | B58: =ROUND(SUMIFS($N$2:$N$24,$D$2:$D$24,A58,$E$2:$E$24,"Active")/SUMIFS($N$2:$N$24,$E$2:$E$24,"Active")*100,1) -> #DIV/0!
...
